Workbook
Name 개인별실기남: '개인실기(남)'!$B$4:$CQ$66
Name 개인별실기남자: '개인실기(남)'!$B$4:$CQ$66
Name 개인별실기여자: '개인실기(여)'!$B$4:$CS$65
Name 고려대: 배점표!$B$70:$I$70
Name 내신성적: #REF!
Name 내신성적여: #REF!
Name 농구남: 배점표!#REF!
Name 농구여: 배점표!#REF!
Name 높뛰남: 배점표!#REF!
Name 높뛰여: 배점표!#REF!
Name 변환점수: #REF!
Name 변환점수: #REF!
Name 수능성적: #REF!
Name 수능성적: #REF!
Name 수능성적: #REF!
Name 수능성적: #REF!
Name 수능성적: #REF!
Name 수능성적목록: #REF!
Name 체조남: 배점표!#REF!
Name 체조여: 배점표!#REF!
Name 체조여: 배점표!#REF!
Name 체조여: 배점표!#REF!

Sheet 사용설명서
B1: 본 자료는 학교체육진흥회 체육인재 상담교사들의 체육대학 진학 상담을 지원하고자 제작하였습니다. 공교육 내에서만 활용하시고 인터넷(밴드, 홈페이지, 게시판 등)을 통한 게시 및 배포는 지양해 주시기 바랍니다. 자료 활용 시 출처를 명시해 주시고 사교육 기관으로의 유출이 발생하지 않도록 각별히 유의해 주시기 바랍니다.
B3: 각 시트에 들어가는 학생이름은 반드시 동일하게 입력되어야 사용 가능합니다. 대학별점수 산출에서 오류를 발견하시면 만든이에게 연락(경기교육통합메신저, 카카오톡)주시기 바랍니다. - 만든이 - 황규훈 : 성남서중학교, 카톡 아이디(hoon0486) 노동기 : 상현고등학교, 카톡 아이디(crazy419)
A5: 첫번째 | B5: 내신(남)/(여) 시트에 상담학생 이름과 내신성적을 입력합니다.[반드시 성별을 구분하여 입력하여야 합니다.]
B6: 내신성적은 유니브 산출점수를 활용하시기 바랍니다.
A36: 두번째 | B36: 개인실기(남)/(여) 시트에서 상담학생 이름과 실기 기록을 입력합니다.[반드시 성별을 구분하여 입력하여야 합니다.]
A66: 세번째 | B66: 학생상담(남)/(여) 시트 상담학생칸 이름 콤보박스에서 상담 학생을 선택합니다.[상담학생의 성별에 맞는 시트를 클릭합니다.]
A95: 네번째 | B95: 상담학생의 대학별 학생내신(내점수)점수와 합격자평균점수, 실기상위권시 지원점수를 활용하여 상담하세요. 안정점수는 최초합 또는 1차 충원합격이 가능한 정도의 점수를 의미하여 기대점수는 충원합격을 기대해 볼만한 점수를 의미합니다. 실기상위권시 지원점수는 대학별 실기성취도가 만점이거나 이에 준하는 매우 우수한 경우를 의미합니다. 일부 비수도권 지역 대학에서는 경쟁률에 의한 입결의 상승과 하락이 다소 크게 나타날 수 있습니다. 이런한 부분까지의 예측은 어려운 점 참고하시기 바랍니다.

Sheet 학생상담(남)
C2: 상담학생 | E2: 황규훈
A4: 지역 | B4: 대학명 | C4: 내점수 | D4: 합격 평균점수 | E4: 실기상위권 지원점수 | F4: 내신환산점 과부족 | G4: 내실기점수 | H4: 내총점수 | I4: 안정점수 | J4: 기대점수 | K4: 2026 모집정원 | L4: 2025 모집정원 | M4: 2024 모집정원 | N4: 2023 모집정원 | O4: 2025 충원합격 | P4: 2024 충원합격 | Q4: 2023 충원합격 | R4: 2022 충원합격 | S4: 2025 경쟁률 | T4: 2024 경쟁률 | U4: 참고사항
A5: ='상담(남)'!A5 -> 경기 | B5: ='상담(남)'!B5 -> 가천대 체육 | C5: ='상담(남)'!C5 -> 300 | D5: ='상담(남)'!D5 -> 294 | E5: 272 | F5: =C5-D5 -> 6 | G5: ='상담(남)'!G5 -> 700 | H5: ='상담(남)'!H5 -> 1000 | I5: ='상담(남)'!I5 -> 984 | J5: ='상담(남)'!J5 -> 973 | K5: ='상담(남)'!K5 -> 40 | L5: ='상담(남)'!L5 -> 40 | M5: ='상담(남)'!M5 -> 30 | N5: ='상담(남)'!N5 -> 20 | ... U5: ='상담(남)'!U5 -> .
A6: ='상담(남)'!A6 -> 강원 | B6: ='상담(남)'!B6 -> 가톨릭관동대 체육교육 | C6: ='상담(남)'!C6 -> 700 | D6: ='상담(남)'!D6 -> 661 | E6: ='상담(남)'!E6 -> 621 | F6: =C6-D6 -> 39 | G6: ='상담(남)'!G6 -> 300 | H6: ='상담(남)'!H6 -> 1000 | I6: ='상담(남)'!I6 -> 945 | J6: ='상담(남)'!J6 -> 921 | K6: ='상담(남)'!K6 -> 20 | L6: ='상담(남)'!L6 -> 20 | M6: ='상담(남)'!M6 -> 20 | N6: ='상담(남)'!N6 -> 20 | ... U6: ='상담(남)'!U6 -> 내신8과목에서 12과목 반영
A7: ='상담(남)'!A7 -> 강원 | B7: ='상담(남)'!B7 -> 가톨릭관동대 스포츠레저 | C7: ='상담(남)'!C7 -> 600 | D7: ='상담(남)'!D7 -> 485 | E7: ='상담(남)'!E7 -> 414 | F7: =C7-D7 -> 115 | G7: ='상담(남)'!G7 -> 400 | H7: ='상담(남)'!H7 -> 1000 | I7: ='상담(남)'!I7 -> 835 | J7: ='상담(남)'!J7 -> 814 | K7: ='상담(남)'!K7 -> 41 | L7: ='상담(남)'!L7 -> 40 | M7: ='상담(남)'!M7 -> 40 | N7: ='상담(남)'!N7 -> 96 | ... U7: ='상담(남)'!U7 -> 내신8과목에서 12과목 반영
A8: ='상담(남)'!A8 -> 강원 | B8: ='상담(남)'!B8 -> 가톨릭관동대 스포츠재활의학 | C8: ='상담(남)'!C8 -> 600 | D8: ='상담(남)'!D8 -> 500 | E8: ='상담(남)'!E8 -> 455 | F8: =C8-D8 -> 100 | G8: ='상담(남)'!G8 -> 400 | H8: ='상담(남)'!H8 -> 1000 | I8: ='상담(남)'!I8 -> 878 | J8: ='상담(남)'!J8 -> 855 | K8: ='상담(남)'!K8 -> 40 | L8: ='상담(남)'!L8 -> 40 | M8: ='상담(남)'!M8 -> 31 | N8: ='상담(남)'!N8 -> 0 | ... U8: ='상담(남)'!U8 -> 실기만점기준 상향 조정
A9: ='상담(남)'!A9 -> 경기 | B9: ='상담(남)'!B9 -> 강남대 체육 | C9: ='상담(남)'!C9 -> 300 | D9: ='상담(남)'!D9 -> 291 | E9: 248 | F9: =C9-D9 -> 9 | G9: ='상담(남)'!G9 -> 676 | H9: ='상담(남)'!H9 -> 976 | I9: ='상담(남)'!I9 -> 979 | J9: 948 | K9: ='상담(남)'!K9 -> 29 | L9: ='상담(남)'!L9 -> 29 | M9: ='상담(남)'!M9 -> 29 | N9: ='상담(남)'!N9 -> 29 | O9: ='상담(남)'!O9 -> 36 | P9: ='상담(남)'!P9 -> 38 | Q9: ='상담(남)'!Q9 -> 38 | R9: ='상담(남)'!R9 -> 19 | ... U9: ='상담(남)'!U9 -> 내신반영변경,실기급간점수 변경
A10: ='상담(남)'!A10 -> 충북 | B10: ='상담(남)'!B10 -> 건국대(글) 스포츠건강 | C10: ='상담(남)'!C10 -> 200 | D10: ='상담(남)'!D10 -> 165 | E10: ='상담(남)'!E10 -> 121 | F10: =C10-D10 -> 35 | G10: ='상담(남)'!G10 -> 520 | H10: ='상담(남)'!H10 -> 720 | I10: ='상담(남)'!I10 -> 951 | J10: ='상담(남)'!J10 -> 921 | K10: ='상담(남)'!K10 -> 20 | L10: ='상담(남)'!L10 -> 20 | M10: ='상담(남)'!M10 -> 22 | N10: ='상담(남)'!N10 -> 18 | ... U10: ='상담(남)'!U10 -> 여자제멀, 남녀 농구 만점상향 조정
A11: ='상담(남)'!A11 -> 경기 | B11: ='상담(남)'!B11 -> 경기대 스포츠과학 | C11: ='상담(남)'!C11 -> 39 | D11: ='상담(남)'!D11 -> 29.49 | E11: ='상담(남)'!E11 -> 29.17 | F11: =C11-D11 -> 9.51 | G11: ='상담(남)'!G11 -> 70 | H11: ='상담(남)'!H11 -> 109 | I11: ='상담(남)'!I11 -> 99.3 | J11: ='상담(남)'!J11 -> 99.17 | K11: ='상담(남)'!K11 -> 19 | L11: ='상담(남)'!L11 -> 10 | M11: ='상담(남)'!M11 -> 10 | N11: ='상담(남)'!N11 -> 10 | ... U11: ='상담(남)'!U11 -> 만점기준 강화 실기반영(10%) 증가
A12: ='상담(남)'!A12 -> 경기 | B12: ='상담(남)'!B12 -> 경기대 체육 | C12: ='상담(남)'!C12 -> 39 | D12: ='상담(남)'!D12 -> 0 | E12: ='상담(남)'!E12 -> 0 | F12: =C12-D12 -> 39 | G12: ='상담(남)'!G12 -> 60 | H12: ='상담(남)'!H12 -> 99 | I12: ='상담(남)'!I12 -> 0 | J12: ='상담(남)'!J12 -> 0 | K12: ='상담(남)'!K12 -> 미선발 | L12: ='상담(남)'!L12 -> 0 | M12: ='상담(남)'!M12 -> 5 | N12: ='상담(남)'!N12 -> 5 | ... U12: ='상담(남)'!U12 -> 수시 폐지 2027 모집정원 전원 수시선발
A13: ='상담(남)'!A13 -> 충북 | B13: ='상담(남)'!B13 -> 극동대 스포츠재활 | C13: ='상담(남)'!C13 -> 200 | D13: ='상담(남)'!D13 -> 160 | E13: ='상담(남)'!E13 -> 116 | F13: =C13-D13 -> 40 | G13: ='상담(남)'!G13 -> 800 | H13: ='상담(남)'!H13 -> 1000 | I13: ='상담(남)'!I13 -> 920 | J13: ='상담(남)'!J13 -> 889.33 | K13: ='상담(남)'!K13 -> 29 | L13: ='상담(남)'!L13 -> 16 | M13: ='상담(남)'!M13 -> 26 | N13: ='상담(남)'!N13 -> 30 | ... U13: ='상담(남)'!U13 -> 실기 4종목 중 3종목 반영/ 경쟁률에 따른 컷라인 예측 불가
A14: ='상담(남)'!A14 -> 충남 | B14: ='상담(남)'!B14 -> 나사렛대 재활스포츠 | C14: ='상담(남)'!C14 -> 100 | D14: ='상담(남)'!D14 -> 85 | E14: ='상담(남)'!E14 -> 72 | F14: =C14-D14 -> 15 | G14: ='상담(남)'!G14 -> 900 | H14: ='상담(남)'!H14 -> 1000 | I14: ='상담(남)'!I14 -> 965 | J14: ='상담(남)'!J14 -> 923 | K14: ='상담(남)'!K14 -> 55 | L14: ='상담(남)'!L14 -> 30 | M14: ='상담(남)'!M14 -> 30 | N14: ='상담(남)'!N14 -> 30 | ... U14: ='상담(남)'!U14 -> 모집정원 대폭증가 컷라인 내려가라~
A15: ='상담(남)'!A15 -> 충남 | B15: ='상담(남)'!B15 -> 남서울대 스포츠건강관리 | C15: ='상담(남)'!C15 -> 258 | D15: ='상담(남)'!D15 -> 210 | E15: ='상담(남)'!E15 -> 154 | F15: =C15-D15 -> 48 | G15: ='상담(남)'!G15 -> 700 | H15: ='상담(남)'!H15 -> 958 | I15: ='상담(남)'!I15 -> 851 | J15: ='상담(남)'!J15 -> 805 | K15: ='상담(남)'!K15 -> 42 | L15: ='상담(남)'!L15 -> 41 | M15: ='상담(남)'!M15 -> 36 | N15: ='상담(남)'!N15 -> 38 | ... U15: ='상담(남)'!U15 -> 좌전굴 폐지 매던 신설
A16: ='상담(남)'!A16 -> 충남 | B16: ='상담(남)'!B16 -> 남서울대 스포츠비즈니스 | C16: ='상담(남)'!C16 -> 249 | D16: ='상담(남)'!D16 -> 210 | E16: ='상담(남)'!E16 -> 136 | F16: =C16-D16 -> 39 | G16: ='상담(남)'!G16 -> 700 | H16: ='상담(남)'!H16 -> 949 | I16: ='상담(남)'!I16 -> 840 | J16: ='상담(남)'!J16 -> 784 | K16: ='상담(남)'!K16 -> 42 | L16: ='상담(남)'!L16 -> 40 | M16: ='상담(남)'!M16 -> 35 | N16: ='상담(남)'!N16 -> 38 | ... U16: ='상담(남)'!U16 -> 3종목 모두 반영으로 총점 하향???
A17: ='상담(남)'!A17 -> 경기 | B17: ='상담(남)'!B17 -> 단국대 체육교육 | C17: ='상담(남)'!C17 -> 198 | D17: ='상담(남)'!D17 -> 686 | E17: ='상담(남)'!E17 -> 668 | F17: =C17-D17 -> -488 | G17: ='상담(남)'!G17 -> 270 | H17: ='상담(남)'!H17 -> 468 | I17: ='상담(남)'!I17 -> 982 | J17: ='상담(남)'!J17 -> 968 | K17: ='상담(남)'!K17 -> 10 | L17: ='상담(남)'!L17 -> 10 | M17: ='상담(남)'!M17 -> 0 | N17: ='상담(남)'!N17 -> 0 | ... T17: ='상담(남)'!T17 -> 0
A18: ='상담(남)'!A18 -> 충남 | B18: ='상담(남)'!B18 -> 단국대 생활체육 | C18: ='상담(남)'!C18 -> 198 | D18: ='상담(남)'!D18 -> 190 | E18: ='상담(남)'!E18 -> 180 | F18: =C18-D18 -> 8 | G18: ='상담(남)'!G18 -> 800 | H18: ='상담(남)'!H18 -> 998 | I18: ='상담(남)'!I18 -> 990 | J18: ='상담(남)'!J18 -> 980 | K18: ='상담(남)'!K18 -> 14 | L18: ='상담(남)'!L18 -> 14 | M18: ='상담(남)'!M18 -> 15 | N18: ='상담(남)'!N18 -> 15 | ... U18: ='상담(남)'!U18 -> .
A19: ='상담(남)'!A19 -> 충남 | B19: ='상담(남)'!B19 -> 단국대 운동처방재활 | C19: ='상담(남)'!C19 -> 198 | D19: ='상담(남)'!D19 -> 194.8 | E19: ='상담(남)'!E19 -> 192.2 | F19: =C19-D19 -> 3.2 | G19: ='상담(남)'!G19 -> 800 | H19: ='상담(남)'!H19 -> 998 | I19: ='상담(남)'!I19 -> 0 | J19: ='상담(남)'!J19 -> 0 | K19: ='상담(남)'!K19 -> 미선발 | L19: ='상담(남)'!L19 -> 5 | M19: ='상담(남)'!M19 -> 5 | N19: ='상담(남)'!N19 -> 6 | ... U19: ='상담(남)'!U19 -> 실기전형 미선발/교과전형 선발
A20: ='상담(남)'!A20 -> 대전 | B20: ='상담(남)'!B20 -> 대전대 스포츠건강재활 | C20: ='상담(남)'!C20 -> 400 | D20: ='상담(남)'!D20 -> 352 | E20: ='상담(남)'!E20 -> 330 | F20: =C20-D20 -> 48 | G20: ='상담(남)'!G20 -> 585 | H20: ='상담(남)'!H20 -> 985 | I20: ='상담(남)'!I20 -> 942 | J20: ='상담(남)'!J20 -> 930 | K20: ='상담(남)'!K20 -> 27 | L20: ='상담(남)'!L20 -> 25 | M20: ='상담(남)'!M20 -> 25 | N20: ='상담(남)'!N20 -> 25 | ... U20: ='상담(남)'!U20 -> .
A21: ='상담(남)'!A21 -> 대전 | B21: ='상담(남)'!B21 -> 대전대 스포츠운동과학 | C21: ='상담(남)'!C21 -> 400 | D21: ='상담(남)'!D21 -> 348 | E21: ='상담(남)'!E21 -> 320 | F21: =C21-D21 -> 52 | G21: ='상담(남)'!G21 -> 585 | H21: ='상담(남)'!H21 -> 985 | I21: ='상담(남)'!I21 -> 938 | J21: ='상담(남)'!J21 -> 920 | K21: ='상담(남)'!K21 -> 32 | L21: ='상담(남)'!L21 -> 32 | M21: ='상담(남)'!M21 -> 23 | N21: ='상담(남)'!N21 -> 20 | ... U21: ='상담(남)'!U21 -> .
A22: ='상담(남)'!A22 -> 경기 | B22: ='상담(남)'!B22 -> 대진대 스포츠겅강과학 | C22: ='상담(남)'!C22 -> 200 | D22: ='상담(남)'!D22 -> 184 | E22: ='상담(남)'!E22 -> 179.3 | F22: =C22-D22 -> 16 | G22: ='상담(남)'!G22 -> 800 | H22: ='상담(남)'!H22 -> 1000 | I22: ='상담(남)'!I22 -> 984 | J22: ='상담(남)'!J22 -> 979.3 | K22: ='상담(남)'!K22 -> 25 | L22: ='상담(남)'!L22 -> 25 | M22: ='상담(남)'!M22 -> 25 | N22: ='상담(남)'!N22 -> 22 | ... U22: ='상담(남)'!U22 -> 진로선택3과목 반영에서 5과목 반영
A23: ='상담(남)'!A23 -> 서울 | B23: ='상담(남)'!B23 -> 동국대 체육교육 | C23: ='상담(남)'!C23 -> 300 | D23: ='상담(남)'!D23 -> 298.4 | E23: ='상담(남)'!E23 -> 294.3 | F23: =C23-D23 -> 1.6 | G23: ='상담(남)'!G23 -> 700 | H23: ='상담(남)'!H23 -> 1000 | I23: ='상담(남)'!I23 -> 996.5 | J23: ='상담(남)'!J23 -> 994.3 | K23: ='상담(남)'!K23 -> 22 | L23: ='상담(남)'!L23 -> 23 | M23: ='상담(남)'!M23 -> 23 | N23: ='상담(남)'!N23 -> 23 | ... U23: ='상담(남)'!U23 -> 실기기본점수 50점
A24: ='상담(남)'!A24 -> 대전 | B24: ='상담(남)'!B24 -> 목원대 스포츠건강관리 | C24: ='상담(남)'!C24 -> 92 | D24: ='상담(남)'!D24 -> 86 | E24: ='상담(남)'!E24 -> 50 | F24: =C24-D24 -> 6 | G24: ='상담(남)'!G24 -> 900 | H24: ='상담(남)'!H24 -> 992 | I24: ='상담(남)'!I24 -> 918 | J24: ='상담(남)'!J24 -> 888 | K24: ='상담(남)'!K24 -> 30 | L24: ='상담(남)'!L24 -> 33 | M24: ='상담(남)'!M24 -> 33 | N24: ='상담(남)'!N24 -> 54 | ... U24: ='상담(남)'!U24 -> .
A25: ='상담(남)'!A25 -> 충남 | B25: ='상담(남)'!B25 -> 백석대 특수체육교육 | C25: ='상담(남)'!C25 -> 400 | D25: ='상담(남)'!D25 -> 552 | E25: ='상담(남)'!E25 -> 516 | F25: =C25-D25 -> -152 | G25: ='상담(남)'!G25 -> 400 | H25: ='상담(남)'!H25 -> 800 | I25: ='상담(남)'!I25 -> 930.67 | J25: ='상담(남)'!J25 -> 916 | K25: ='상담(남)'!K25 -> 27 | L25: ='상담(남)'!L25 -> 27 | M25: ='상담(남)'!M25 -> 27 | N25: ='상담(남)'!N25 -> 26 | ... U25: ='상담(남)'!U25 -> .
A26: ='상담(남)'!A26 -> 충남 | B26: ='상담(남)'!B26 -> 백석대 스포츠과학 | C26: ='상담(남)'!C26 -> 600 | D26: ='상담(남)'!D26 -> 349 | E26: ='상담(남)'!E26 -> 323 | F26: =C26-D26 -> 251 | G26: ='상담(남)'!G26 -> 600 | H26: ='상담(남)'!H26 -> 1200 | I26: ='상담(남)'!I26 -> 941 | J26: ='상담(남)'!J26 -> 923 | K26: ='상담(남)'!K26 -> 73 | L26: ='상담(남)'!L26 -> 73 | M26: ='상담(남)'!M26 -> 75 | N26: ='상담(남)'!N26 -> 46 | ... U26: ='상담(남)'!U26 -> .
A27: ='상담(남)'!A27 -> 서울 | B27: ='상담(남)'!B27 -> 삼육대 체육 | C27: ='상담(남)'!C27 -> 400 | D27: ='상담(남)'!D27 -> 392 | E27: ='상담(남)'!E27 -> 386 | F27: =C27-D27 -> 8 | G27: ='상담(남)'!G27 -> 600 | H27: ='상담(남)'!H27 -> 1000 | I27: ='상담(남)'!I27 -> 990 | J27: ='상담(남)'!J27 -> 986 | K27: ='상담(남)'!K27 -> 12 | L27: ='상담(남)'!L27 -> 10 | M27: ='상담(남)'!M27 -> 11 | N27: ='상담(남)'!N27 -> 9 | ... U27: ='상담(남)'!U27 -> 진로선택3과목 반영에서 이수전과목 반영
A28: ='상담(남)'!A28 -> 서울 | B28: ='상담(남)'!B28 -> 상명대 스포츠건강 | C28: ='상담(남)'!C28 -> 300 | D28: ='상담(남)'!D28 -> 282 | E28: ='상담(남)'!E28 -> 235 | F28: =C28-D28 -> 18 | G28: ='상담(남)'!G28 -> 675.5 | H28: ='상담(남)'!H28 -> 975.5 | I28: ='상담(남)'!I28 -> 961 | J28: ='상담(남)'!J28 -> 935 | K28: ='상담(남)'!K28 -> 12 | L28: ='상담(남)'!L28 -> 12 | M28: ='상담(남)'!M28 -> 0 | N28: ='상담(남)'!N28 -> 0 | ... T28: ='상담(남)'!T28 -> 0
A29: ='상담(남)'!A29 -> 충남 | B29: ='상담(남)'!B29 -> 상명대(천안) 스포츠융합 | C29: ='상담(남)'!C29 -> 400 | D29: ='상담(남)'!D29 -> 357 | E29: ='상담(남)'!E29 -> 288 | F29: =C29-D29 -> 43 | G29: ='상담(남)'!G29 -> 590 | H29: ='상담(남)'!H29 -> 990 | I29: ='상담(남)'!I29 -> 910 | J29: ='상담(남)'!J29 -> 888 | K29: ='상담(남)'!K29 -> 38 | L29: ='상담(남)'!L29 -> 38 | M29: ='상담(남)'!M29 -> 38 | N29: ='상담(남)'!N29 -> 43 | ... U29: ='상담(남)'!U29 -> .
A30: ='상담(남)'!A30 -> 강원 | B30: ='상담(남)'!B30 -> 상지대 체육 | C30: ='상담(남)'!C30 -> 300 | D30: ='상담(남)'!D30 -> 233 | E30: ='상담(남)'!E30 -> 197 | F30: =C30-D30 -> 67 | G30: ='상담(남)'!G30 -> 700 | H30: ='상담(남)'!H30 -> 1000 | I30: ='상담(남)'!I30 -> 920 | J30: ='상담(남)'!J30 -> 897 | K30: ='상담(남)'!K30 -> 40 | L30: ='상담(남)'!L30 -> 40 | M30: ='상담(남)'!M30 -> 55 | N30: ='상담(남)'!N30 -> 60 | ... U30: ='상담(남)'!U30 -> .
A31: ='상담(남)'!A31 -> 서울 | B31: ='상담(남)'!B31 -> 서경대 스포츠&테크놀러지 | C31: ='상담(남)'!C31 -> 250 | D31: ='상담(남)'!D31 -> 294 | E31: ='상담(남)'!E31 -> 281 | F31: =C31-D31 -> -44 | G31: ='상담(남)'!G31 -> 400 | H31: ='상담(남)'!H31 -> 650 | I31: ='상담(남)'!I31 -> 687.33 | J31: ='상담(남)'!J31 -> 680.67 | K31: ='상담(남)'!K31 -> 30 | L31: ='상담(남)'!L31 -> 30 | M31: ='상담(남)'!M31 -> 0 | N31: ='상담(남)'!N31 -> 0 | ... T31: ='상담(남)'!T31 -> 19.90
A32: ='상담(남)'!A32 -> 충남 | B32: ='상담(남)'!B32 -> 서원대 체육교육 | C32: ='상담(남)'!C32 -> 600 | D32: ='상담(남)'!D32 -> 588 | E32: ='상담(남)'!E32 -> 576 | F32: =C32-D32 -> 12 | G32: ='상담(남)'!G32 -> 400 | H32: ='상담(남)'!H32 -> 1000 | I32: ='상담(남)'!I32 -> 981.6 | J32: ='상담(남)'!J32 -> 976 | K32: ='상담(남)'!K32 -> 28 | L32: ='상담(남)'!L32 -> 23 | M32: ='상담(남)'!M32 -> 23 | N32: ='상담(남)'!N32 -> 23 | ... U32: ='상담(남)'!U32 -> 실기기본점수 80점/실기변경/변별력 상승
A33: ='상담(남)'!A33 -> 충남 | B33: ='상담(남)'!B33 -> 서원대 레저스포츠 | C33: ='상담(남)'!C33 -> 200 | D33: ='상담(남)'!D33 -> 190.5 | E33: ='상담(남)'!E33 -> 170 | F33: =C33-D33 -> 9.5 | G33: ='상담(남)'!G33 -> 800 | H33: ='상담(남)'!H33 -> 1000 | I33: ='상담(남)'!I33 -> 978.3 | J33: ='상담(남)'!J33 -> 963.6 | K33: ='상담(남)'!K33 -> 31 | L33: ='상담(남)'!L33 -> 48 | M33: ='상담(남)'!M33 -> 45 | N33: ='상담(남)'!N33 -> 58 | ... U33: ='상담(남)'!U33 -> 실기기본점수 160점/변별력 상승
A34: ='상담(남)'!A34 -> 충남 | B34: ='상담(남)'!B34 -> 서원대 헬스케어운동 | C34: ='상담(남)'!C34 -> 200 | D34: ='상담(남)'!D34 -> 193 | E34: ='상담(남)'!E34 -> 175 | F34: =C34-D34 -> 7 | G34: ='상담(남)'!G34 -> 800 | H34: ='상담(남)'!H34 -> 1000 | I34: ='상담(남)'!I34 -> 986.6 | J34: ='상담(남)'!J34 -> 971.4 | K34: ='상담(남)'!K34 -> 25 | L34: ='상담(남)'!L34 -> 25 | M34: ='상담(남)'!M34 -> 25 | N34: ='상담(남)'!N34 -> 30 | ... U34: ='상담(남)'!U34 -> 실기기본점수 160점/변별력 상승
A35: ='상담(남)'!A35 -> 충남 | B35: ='상담(남)'!B35 -> 선문대 스포츠과학 | C35: ='상담(남)'!C35 -> 200 | D35: ='상담(남)'!D35 -> 120 | E35: ='상담(남)'!E35 -> 40 | F35: =C35-D35 -> 80 | G35: ='상담(남)'!G35 -> 800 | H35: ='상담(남)'!H35 -> 1000 | I35: ='상담(남)'!I35 -> 830 | J35: ='상담(남)'!J35 -> 795 | K35: ='상담(남)'!K35 -> 27 | L35: ='상담(남)'!L35 -> 26 | M35: ='상담(남)'!M35 -> 24 | N35: ='상담(남)'!N35 -> 25 | ... U35: ='상담(남)'!U35 -> .
A36: ='상담(남)'!A36 -> 충남 | B36: ='상담(남)'!B36 -> 선문대 피트니스재활 | C36: ='상담(남)'!C36 -> 180 | D36: ='상담(남)'!D36 -> 120 | E36: ='상담(남)'!E36 -> 40 | F36: =C36-D36 -> 60 | G36: ='상담(남)'!G36 -> 800 | H36: ='상담(남)'!H36 -> 980 | I36: ='상담(남)'!I36 -> 780 | J36: ='상담(남)'!J36 -> 734 | K36: ='상담(남)'!K36 -> 27 | L36: ='상담(남)'!L36 -> 25 | M36: ='상담(남)'!M36 -> 24 | N36: ='상담(남)'!N36 -> 25 | ... U36: ='상담(남)'!U36 -> .
A37: ='상담(남)'!A37 -> 경기 | B37: ='상담(남)'!B37 -> 성결대 체육교육 | C37: ='상담(남)'!C37 -> 400 | D37: ='상담(남)'!D37 -> 395 | E37: ='상담(남)'!E37 -> 385 | F37: =C37-D37 -> 5 | G37: ='상담(남)'!G37 -> 600 | H37: ='상담(남)'!H37 -> 1000 | I37: ='상담(남)'!I37 -> 991 | J37: ='상담(남)'!J37 -> 985 | K37: ='상담(남)'!K37 -> 14 | L37: ='상담(남)'!L37 -> 14 | M37: ='상담(남)'!M37 -> 14 | N37: ='상담(남)'!N37 -> 8 | ... U37: ='상담(남)'!U37 -> 내신반영방법 변경/교과점수 상승
A38: ='상담(남)'!A38 -> 충북 | B38: ='상담(남)'!B38 -> 세명대 생활체육 | C38: ='상담(남)'!C38 -> 200 | D38: ='상담(남)'!D38 -> 120 | E38: ='상담(남)'!E38 -> 40 | F38: =C38-D38 -> 80 | G38: ='상담(남)'!G38 -> 800 | H38: ='상담(남)'!H38 -> 1000 | I38: ='상담(남)'!I38 -> 860 | J38: ='상담(남)'!J38 -> 740 | K38: ='상담(남)'!K38 -> 30 | L38: ='상담(남)'!L38 -> 25 | M38: ='상담(남)'!M38 -> 25 | N38: ='상담(남)'!N38 -> 25 | ... U38: ='상담(남)'!U38 -> 윗몸폐지 농구신설 실기반영비율 증가
A39: ='상담(남)'!A39 -> 경기 | B39: ='상담(남)'!B39 -> 수원대 스포츠과학부 | C39: ='상담(남)'!C39 -> 400 | D39: ='상담(남)'!D39 -> 380 | E39: ='상담(남)'!E39 -> 367 | F39: =C39-D39 -> 20 | G39: ='상담(남)'!G39 -> 600 | H39: ='상담(남)'!H39 -> 1000 | I39: ='상담(남)'!I39 -> 974 | J39: ='상담(남)'!J39 -> 967 | K39: ='상담(남)'!K39 -> 기초 20 축구 13 농구 7 체조 5 | L39: ='상담(남)'!L39 -> 기초 20 축구 13 농구 7 체조 5 | M39: ='상담(남)'!M39 -> 20 | N39: ='상담(남)'!N39 -> 20 | ... U39: ='상담(남)'!U39 -> 기초체력 기준
A40: ='상담(남)'!A40 -> 충남 | B40: ='상담(남)'!B40 -> 순천향대 스포츠과학 | C40: ='상담(남)'!C40 -> 300 | D40: ='상담(남)'!D40 -> 276 | E40: ='상담(남)'!E40 -> 252 | F40: =C40-D40 -> 24 | G40: ='상담(남)'!G40 -> 692.22222 | H40: ='상담(남)'!H40 -> 992.22222 | I40: ='상담(남)'!I40 -> 962 | J40: ='상담(남)'!J40 -> 952 | K40: ='상담(남)'!K40 -> 16 | L40: ='상담(남)'!L40 -> 16 | M40: ='상담(남)'!M40 -> 17 | N40: ='상담(남)'!N40 -> 17 | ... U40: ='상담(남)'!U40 -> 윗몸폐지 농구신설(45초)
A41: ='상담(남)'!A41 -> 충남 | B41: ='상담(남)'!B41 -> 순천향대 스포츠의학 | C41: ='상담(남)'!C41 -> 400 | D41: ='상담(남)'!D41 -> 382 | E41: ='상담(남)'!E41 -> 369 | F41: =C41-D41 -> 18 | G41: ='상담(남)'!G41 -> 595 | H41: ='상담(남)'!H41 -> 995 | I41: ='상담(남)'!I41 -> 976 | J41: ='상담(남)'!J41 -> 969 | K41: ='상담(남)'!K41 -> 13 | L41: ='상담(남)'!L41 -> 13 | M41: ='상담(남)'!M41 -> 12 | N41: ='상담(남)'!N41 -> 15 | ... U41: ='상담(남)'!U41 -> .
A42: ='상담(남)'!A42 -> 충남 | B42: ='상담(남)'!B42 -> 순천향대 스포츠응용산업 | C42: ='상담(남)'!C42 -> 300 | D42: ='상담(남)'!D42 -> 276 | E42: ='상담(남)'!E42 -> 262 | F42: =C42-D42 -> 24 | G42: ='상담(남)'!G42 -> 696.11111 | H42: ='상담(남)'!H42 -> 996.11111 | I42: ='상담(남)'!I42 -> 968 | J42: ='상담(남)'!J42 -> 962 | K42: ='상담(남)'!K42 -> 20 | L42: ='상담(남)'!L42 -> 20 | M42: ='상담(남)'!M42 -> 19 | N42: ='상담(남)'!N42 -> 19 | ... U42: ='상담(남)'!U42 -> 학과명 변경
...

Sheet 학생상담(여)
C2: 상담학생 | E2: 고춘자
A4: 지역 | B4: 대학명 | C4: 내점수 | D4: 합격자 평균점수 | E4: 실시상위권 지원점수 | F4: 내신환산점 과부족 | G4: 내실기점수 | H4: 내총점 | I4: 안정점수 | J4: 기대점수 | K4: 2026 모집정원 | L4: 2025 모집정원 | M4: 2024 모집정원 | N4: 2023 모집정원 | O4: 2025 충원합격 | P4: 2024 충원합격 | Q4: 2023 충원합격 | R4: 2022 충원합격 | S4: 2025 경쟁률 | T4: 2024 경쟁률 | U4: 참고사항
A5: ='상담(여)'!A5 -> 경기 | B5: ='상담(여)'!B5 -> 가천대 체육 | C5: ='상담(여)'!C5 -> 300 | D5: ='상담(여)'!D5 -> 294 | E5: ='상담(여)'!E5 -> 273 | F5: =C5-D5 -> 6 | G5: ='상담(여)'!G5 -> 700 | H5: ='상담(여)'!H5 -> 1000 | I5: ='상담(여)'!I5 -> 984 | J5: ='상담(여)'!J5 -> 973 | K5: ='상담(여)'!K5 -> 40 | L5: ='상담(여)'!L5 -> 40 | M5: ='상담(여)'!M5 -> 30 | N5: ='상담(여)'!N5 -> 20 | ... U5: ='상담(여)'!U5 -> .
A6: ='상담(여)'!A6 -> 강원 | B6: ='상담(여)'!B6 -> 가톨릭관동대 체육교육 | C6: ='상담(여)'!C6 -> 700 | D6: ='상담(여)'!D6 -> 661 | E6: ='상담(여)'!E6 -> 621 | F6: =C6-D6 -> 39 | G6: ='상담(여)'!G6 -> 300 | H6: ='상담(여)'!H6 -> 1000 | I6: ='상담(여)'!I6 -> 945 | J6: ='상담(여)'!J6 -> 921 | K6: ='상담(여)'!K6 -> 20 | L6: ='상담(여)'!L6 -> 20 | M6: ='상담(여)'!M6 -> 20 | N6: ='상담(여)'!N6 -> 20 | ... U6: ='상담(여)'!U6 -> 내신8과목에서 12과목 반영
A7: ='상담(여)'!A7 -> 강원 | B7: ='상담(여)'!B7 -> 가톨릭관동대 스포츠레저 | C7: ='상담(여)'!C7 -> 600 | D7: ='상담(여)'!D7 -> 485 | E7: ='상담(여)'!E7 -> 414 | F7: =C7-D7 -> 115 | G7: ='상담(여)'!G7 -> 400 | H7: ='상담(여)'!H7 -> 1000 | I7: ='상담(여)'!I7 -> 835 | J7: ='상담(여)'!J7 -> 814 | K7: ='상담(여)'!K7 -> 41 | L7: ='상담(여)'!L7 -> 40 | M7: ='상담(여)'!M7 -> 40 | N7: ='상담(여)'!N7 -> 96 | ... U7: ='상담(여)'!U7 -> 내신8과목에서 12과목 반영
A8: ='상담(여)'!A8 -> 강원 | B8: ='상담(여)'!B8 -> 가톨릭관동대 스포츠재활의학 | C8: ='상담(여)'!C8 -> 600 | D8: ='상담(여)'!D8 -> 500 | E8: ='상담(여)'!E8 -> 455 | F8: =C8-D8 -> 100 | G8: ='상담(여)'!G8 -> 400 | H8: ='상담(여)'!H8 -> 1000 | I8: ='상담(여)'!I8 -> 878 | J8: ='상담(여)'!J8 -> 855 | K8: ='상담(여)'!K8 -> 40 | L8: ='상담(여)'!L8 -> 40 | M8: ='상담(여)'!M8 -> 31 | N8: ='상담(여)'!N8 -> 0 | ... U8: ='상담(여)'!U8 -> 실기만점기준 상향 조정
A9: ='상담(여)'!A9 -> 경기 | B9: ='상담(여)'!B9 -> 강남대 체육 | C9: ='상담(여)'!C9 -> 300 | D9: ='상담(여)'!D9 -> 291 | E9: ='상담(여)'!E9 -> 271 | F9: =C9-D9 -> 9 | G9: ='상담(여)'!G9 -> 688 | H9: ='상담(여)'!H9 -> 988 | I9: ='상담(여)'!I9 -> 979 | J9: ='상담(여)'!J9 -> 971 | K9: ='상담(여)'!K9 -> 29 | L9: ='상담(여)'!L9 -> 29 | M9: ='상담(여)'!M9 -> 29 | N9: ='상담(여)'!N9 -> 29 | ... U9: ='상담(여)'!U9 -> 내신반영변경,실기급간점수 변경
A10: ='상담(여)'!A10 -> 충북 | B10: ='상담(여)'!B10 -> 건국대(글) 스포츠건강 | C10: ='상담(여)'!C10 -> 200 | D10: ='상담(여)'!D10 -> 165 | E10: ='상담(여)'!E10 -> 121 | F10: =C10-D10 -> 35 | G10: ='상담(여)'!G10 -> 720 | H10: ='상담(여)'!H10 -> 920 | I10: ='상담(여)'!I10 -> 951 | J10: ='상담(여)'!J10 -> 921 | K10: ='상담(여)'!K10 -> 20 | L10: ='상담(여)'!L10 -> 20 | M10: ='상담(여)'!M10 -> 22 | N10: ='상담(여)'!N10 -> 18 | ... U10: ='상담(여)'!U10 -> 여자제멀, 남녀 농구 만점상향 조정
A11: ='상담(여)'!A11 -> 경기 | B11: ='상담(여)'!B11 -> 경기대 스포츠과학 | C11: ='상담(여)'!C11 -> 39.8 | D11: ='상담(여)'!D11 -> 29.49 | E11: ='상담(여)'!E11 -> 29.17 | F11: =C11-D11 -> 10.31 | G11: ='상담(여)'!G11 -> 70 | H11: ='상담(여)'!H11 -> 109.8 | I11: ='상담(여)'!I11 -> 99.3 | J11: ='상담(여)'!J11 -> 99.17 | K11: ='상담(여)'!K11 -> 19 | L11: ='상담(여)'!L11 -> 10 | M11: ='상담(여)'!M11 -> 10 | N11: ='상담(여)'!N11 -> 10 | ... U11: ='상담(여)'!U11 -> 만점기준 강화 실기반영(10%) 증가
A12: ='상담(여)'!A12 -> 경기 | B12: ='상담(여)'!B12 -> 경기대 체육 | C12: ='상담(여)'!C12 -> 36.55 | D12: ='상담(여)'!D12 -> 0 | E12: ='상담(여)'!E12 -> 0 | F12: =C12-D12 -> 36.55 | G12: ='상담(여)'!G12 -> 60 | H12: ='상담(여)'!H12 -> 96.55 | I12: ='상담(여)'!I12 -> 0 | J12: ='상담(여)'!J12 -> 0 | K12: ='상담(여)'!K12 -> 미선발 | L12: ='상담(여)'!L12 -> 0 | M12: ='상담(여)'!M12 -> 5 | N12: ='상담(여)'!N12 -> 5 | ... U12: ='상담(여)'!U12 -> 수시 폐지 2027 모집정원 전원 수시선발
A13: ='상담(여)'!A13 -> 충북 | B13: ='상담(여)'!B13 -> 극동대 스포츠재활 | C13: ='상담(여)'!C13 -> 200 | D13: ='상담(여)'!D13 -> 160 | E13: ='상담(여)'!E13 -> 116 | F13: =C13-D13 -> 40 | G13: ='상담(여)'!G13 -> 800 | H13: ='상담(여)'!H13 -> 1000 | I13: ='상담(여)'!I13 -> 920 | J13: ='상담(여)'!J13 -> 889.33 | K13: ='상담(여)'!K13 -> 29 | L13: ='상담(여)'!L13 -> 16 | M13: ='상담(여)'!M13 -> 26 | N13: ='상담(여)'!N13 -> 30 | ... U13: ='상담(여)'!U13 -> 실기 4종목 중 3종목 반영/ 경쟁률에 따른 컷라인 예측 불가
A14: ='상담(여)'!A14 -> 충남 | B14: ='상담(여)'!B14 -> 나사렛대 재활스포츠 | C14: ='상담(여)'!C14 -> 100 | D14: ='상담(여)'!D14 -> 85 | E14: ='상담(여)'!E14 -> 72 | F14: =C14-D14 -> 15 | G14: ='상담(여)'!G14 -> 900 | H14: ='상담(여)'!H14 -> 1000 | I14: ='상담(여)'!I14 -> 965 | J14: ='상담(여)'!J14 -> 923 | K14: ='상담(여)'!K14 -> 55 | L14: ='상담(여)'!L14 -> 30 | M14: ='상담(여)'!M14 -> 30 | N14: ='상담(여)'!N14 -> 30 | ... U14: ='상담(여)'!U14 -> 모집정원 대폭증가 컷라인 내려가라~
A15: ='상담(여)'!A15 -> 충남 | B15: ='상담(여)'!B15 -> 남서울대 스포츠건강관리 | C15: ='상담(여)'!C15 -> 300 | D15: ='상담(여)'!D15 -> 210 | E15: ='상담(여)'!E15 -> 154 | F15: =C15-D15 -> 90 | G15: ='상담(여)'!G15 -> 700 | H15: ='상담(여)'!H15 -> 1000 | I15: ='상담(여)'!I15 -> 851 | J15: ='상담(여)'!J15 -> 805 | K15: ='상담(여)'!K15 -> 42 | L15: ='상담(여)'!L15 -> 41 | M15: ='상담(여)'!M15 -> 36 | N15: ='상담(여)'!N15 -> 38 | ... U15: ='상담(여)'!U15 -> 좌전굴 폐지 매던 신설
A16: ='상담(여)'!A16 -> 충남 | B16: ='상담(여)'!B16 -> 남서울대 스포츠비즈니스 | C16: ='상담(여)'!C16 -> 300 | D16: ='상담(여)'!D16 -> 210 | E16: ='상담(여)'!E16 -> 136 | F16: =C16-D16 -> 90 | G16: ='상담(여)'!G16 -> 700 | H16: ='상담(여)'!H16 -> 1000 | I16: ='상담(여)'!I16 -> 840 | J16: ='상담(여)'!J16 -> 784 | K16: ='상담(여)'!K16 -> 42 | L16: ='상담(여)'!L16 -> 40 | M16: ='상담(여)'!M16 -> 35 | N16: ='상담(여)'!N16 -> 38 | ... U16: ='상담(여)'!U16 -> 3종목 모두 반영으로 총점 하향???
A17: ='상담(여)'!A17 -> 경기 | B17: ='상담(여)'!B17 -> 단국대 체육교육 | C17: ='상담(여)'!C17 -> 0 | D17: ='상담(여)'!D17 -> 686 | E17: ='상담(여)'!E17 -> 668 | F17: =C17-D17 -> -686 | G17: ='상담(여)'!G17 -> 352 | H17: ='상담(여)'!H17 -> 352 | I17: ='상담(여)'!I17 -> 982 | J17: ='상담(여)'!J17 -> 968 | K17: ='상담(여)'!K17 -> 10 | L17: ='상담(여)'!L17 -> 10 | M17: ='상담(여)'!M17 -> 0 | N17: ='상담(여)'!N17 -> 0 | ... T17: ='상담(여)'!T17 -> 0
A18: ='상담(여)'!A18 -> 충남 | B18: ='상담(여)'!B18 -> 단국대 생활체육 | C18: ='상담(여)'!C18 -> 197.5 | D18: ='상담(여)'!D18 -> 190 | E18: ='상담(여)'!E18 -> 180 | F18: =C18-D18 -> 7.5 | G18: ='상담(여)'!G18 -> 800 | H18: ='상담(여)'!H18 -> 997.5 | I18: ='상담(여)'!I18 -> 990 | J18: ='상담(여)'!J18 -> 980 | K18: ='상담(여)'!K18 -> 14 | L18: ='상담(여)'!L18 -> 14 | M18: ='상담(여)'!M18 -> 15 | N18: ='상담(여)'!N18 -> 15 | ... U18: ='상담(여)'!U18 -> .
A19: ='상담(여)'!A19 -> 충남 | B19: ='상담(여)'!B19 -> 단국대 운동처방재활 | C19: ='상담(여)'!C19 -> 197.5 | D19: ='상담(여)'!D19 -> 194.8 | E19: ='상담(여)'!E19 -> 192.2 | F19: =C19-D19 -> 2.7 | G19: ='상담(여)'!G19 -> 800 | H19: ='상담(여)'!H19 -> 997.5 | I19: ='상담(여)'!I19 -> 0 | J19: ='상담(여)'!J19 -> 0 | K19: ='상담(여)'!K19 -> 미선발 | L19: ='상담(여)'!L19 -> 5 | M19: ='상담(여)'!M19 -> 5 | N19: ='상담(여)'!N19 -> 6 | ... U19: ='상담(여)'!U19 -> 실기전형 미선발/교과전형 선발
A20: ='상담(여)'!A20 -> 대전 | B20: ='상담(여)'!B20 -> 대전대 스포츠건강재활 | C20: ='상담(여)'!C20 -> 400 | D20: ='상담(여)'!D20 -> 352 | E20: ='상담(여)'!E20 -> 330 | F20: =C20-D20 -> 48 | G20: ='상담(여)'!G20 -> 600 | H20: ='상담(여)'!H20 -> 1000 | I20: ='상담(여)'!I20 -> 942 | J20: ='상담(여)'!J20 -> 930 | K20: ='상담(여)'!K20 -> 27 | L20: ='상담(여)'!L20 -> 25 | M20: ='상담(여)'!M20 -> 25 | N20: ='상담(여)'!N20 -> 25 | ... U20: ='상담(여)'!U20 -> .
A21: ='상담(여)'!A21 -> 대전 | B21: ='상담(여)'!B21 -> 대전대 스포츠운동과학 | C21: ='상담(여)'!C21 -> 400 | D21: ='상담(여)'!D21 -> 348 | E21: ='상담(여)'!E21 -> 320 | F21: =C21-D21 -> 52 | G21: ='상담(여)'!G21 -> 600 | H21: ='상담(여)'!H21 -> 1000 | I21: ='상담(여)'!I21 -> 938 | J21: ='상담(여)'!J21 -> 920 | K21: ='상담(여)'!K21 -> 32 | L21: ='상담(여)'!L21 -> 32 | M21: ='상담(여)'!M21 -> 23 | N21: ='상담(여)'!N21 -> 20 | ... U21: ='상담(여)'!U21 -> .
A22: ='상담(여)'!A22 -> 경기 | B22: ='상담(여)'!B22 -> 대진대 스포츠겅강과학 | C22: ='상담(여)'!C22 -> 200 | D22: ='상담(여)'!D22 -> 184 | E22: ='상담(여)'!E22 -> 179.3 | F22: =C22-D22 -> 16 | G22: ='상담(여)'!G22 -> 800 | H22: ='상담(여)'!H22 -> 1000 | I22: ='상담(여)'!I22 -> 984 | J22: ='상담(여)'!J22 -> 979.3 | K22: ='상담(여)'!K22 -> 25 | L22: ='상담(여)'!L22 -> 25 | M22: ='상담(여)'!M22 -> 25 | N22: ='상담(여)'!N22 -> 22 | ... U22: ='상담(여)'!U22 -> 진로선택3과목 반영에서 5과목 반영
A23: ='상담(여)'!A23 -> 서울 | B23: ='상담(여)'!B23 -> 동국대 체육교육 | C23: ='상담(여)'!C23 -> 300 | D23: ='상담(여)'!D23 -> 298.4 | E23: ='상담(여)'!E23 -> 294.3 | F23: =C23-D23 -> 1.6 | G23: ='상담(여)'!G23 -> 700 | H23: ='상담(여)'!H23 -> 1000 | I23: ='상담(여)'!I23 -> 996.5 | J23: ='상담(여)'!J23 -> 994.3 | K23: ='상담(여)'!K23 -> 22 | L23: ='상담(여)'!L23 -> 23 | M23: ='상담(여)'!M23 -> 23 | N23: ='상담(여)'!N23 -> 23 | ... U23: ='상담(여)'!U23 -> 실기기본점수 50점
A24: ='상담(여)'!A24 -> 서울 | B24: ='상담(여)'!B24 -> 동덕여대 체육 | C24: ='상담(여)'!C24 -> 199.99 | D24: ='상담(여)'!D24 -> 396.8 | E24: ='상담(여)'!E24 -> 392.8 | F24: =C24-D24 -> -196.81 | G24: ='상담(여)'!G24 -> 528 | H24: ='상담(여)'!H24 -> 727.99 | I24: ='상담(여)'!I24 -> 0 | J24: ='상담(여)'!J24 -> 0 | K24: ='상담(여)'!K24 -> 일반학생미선발 | L24: ='상담(여)'!L24 -> 0 | M24: ='상담(여)'!M24 -> 0 | N24: ='상담(여)'!N24 -> 0 | ... U24: ='상담(여)'!U24 -> 일반학생 미선발
A25: ='상담(여)'!A25 -> 대전 | B25: ='상담(여)'!B25 -> 목원대 스포츠건강관리 | C25: ='상담(여)'!C25 -> 99.85 | D25: ='상담(여)'!D25 -> 86 | E25: ='상담(여)'!E25 -> 50 | F25: =C25-D25 -> 13.85 | G25: ='상담(여)'!G25 -> 900 | H25: ='상담(여)'!H25 -> 999.85 | I25: ='상담(여)'!I25 -> 918 | J25: ='상담(여)'!J25 -> 888 | K25: ='상담(여)'!K25 -> 30 | L25: ='상담(여)'!L25 -> 33 | M25: ='상담(여)'!M25 -> 33 | N25: ='상담(여)'!N25 -> 54 | ... U25: ='상담(여)'!U25 -> .
A26: ='상담(여)'!A26 -> 충남 | B26: ='상담(여)'!B26 -> 백석대 특수체육교육 | C26: ='상담(여)'!C26 -> 400 | D26: ='상담(여)'!D26 -> 552 | E26: ='상담(여)'!E26 -> 516 | F26: =C26-D26 -> -152 | G26: ='상담(여)'!G26 -> 400 | H26: ='상담(여)'!H26 -> 800 | I26: ='상담(여)'!I26 -> 930.67 | J26: ='상담(여)'!J26 -> 916 | K26: ='상담(여)'!K26 -> 27 | L26: ='상담(여)'!L26 -> 27 | M26: ='상담(여)'!M26 -> 27 | N26: ='상담(여)'!N26 -> 26 | ... U26: ='상담(여)'!U26 -> .
A27: ='상담(여)'!A27 -> 충남 | B27: ='상담(여)'!B27 -> 백석대 스포츠과학 | C27: ='상담(여)'!C27 -> 600 | D27: ='상담(여)'!D27 -> 349 | E27: ='상담(여)'!E27 -> 323 | F27: =C27-D27 -> 251 | G27: ='상담(여)'!G27 -> 600 | H27: ='상담(여)'!H27 -> 1200 | I27: ='상담(여)'!I27 -> 941 | J27: ='상담(여)'!J27 -> 923 | K27: ='상담(여)'!K27 -> 73 | L27: ='상담(여)'!L27 -> 73 | M27: ='상담(여)'!M27 -> 75 | N27: ='상담(여)'!N27 -> 46 | ... U27: ='상담(여)'!U27 -> .
A28: ='상담(여)'!A28 -> 서울 | B28: ='상담(여)'!B28 -> 삼육대 체육 | C28: ='상담(여)'!C28 -> 395 | D28: ='상담(여)'!D28 -> 392 | E28: ='상담(여)'!E28 -> 386 | F28: =C28-D28 -> 3 | G28: ='상담(여)'!G28 -> 600 | H28: ='상담(여)'!H28 -> 995 | I28: ='상담(여)'!I28 -> 990 | J28: ='상담(여)'!J28 -> 986 | K28: ='상담(여)'!K28 -> 12 | L28: ='상담(여)'!L28 -> 10 | M28: ='상담(여)'!M28 -> 11 | N28: ='상담(여)'!N28 -> 9 | ... U28: ='상담(여)'!U28 -> 진로선택3과목 반영에서 이수전과목 반영
A29: ='상담(여)'!A29 -> 서울 | B29: ='상담(여)'!B29 -> 상명대 스포츠건강 | C29: ='상담(여)'!C29 -> 300 | D29: ='상담(여)'!D29 -> 282 | E29: ='상담(여)'!E29 -> 235 | F29: =C29-D29 -> 18 | G29: ='상담(여)'!G29 -> 226.33333 | H29: ='상담(여)'!H29 -> 526.33333 | I29: ='상담(여)'!I29 -> 961 | J29: ='상담(여)'!J29 -> 935 | K29: ='상담(여)'!K29 -> 12 | L29: ='상담(여)'!L29 -> 12 | M29: ='상담(여)'!M29 -> 0 | N29: ='상담(여)'!N29 -> 0 | ... T29: ='상담(여)'!T29 -> 0
A30: ='상담(여)'!A30 -> 충남 | B30: ='상담(여)'!B30 -> 상명대(천안) 스포츠융합 | C30: ='상담(여)'!C30 -> 400 | D30: ='상담(여)'!D30 -> 357 | E30: ='상담(여)'!E30 -> 288 | F30: =C30-D30 -> 43 | G30: ='상담(여)'!G30 -> 600 | H30: ='상담(여)'!H30 -> 1000 | I30: ='상담(여)'!I30 -> 910 | J30: ='상담(여)'!J30 -> 888 | K30: ='상담(여)'!K30 -> 38 | L30: ='상담(여)'!L30 -> 38 | M30: ='상담(여)'!M30 -> 38 | N30: ='상담(여)'!N30 -> 43 | ... U30: ='상담(여)'!U30 -> .
A31: ='상담(여)'!A31 -> 강원 | B31: ='상담(여)'!B31 -> 상지대 체육 | C31: ='상담(여)'!C31 -> 300 | D31: ='상담(여)'!D31 -> 233 | E31: ='상담(여)'!E31 -> 197 | F31: =C31-D31 -> 67 | G31: ='상담(여)'!G31 -> 700 | H31: ='상담(여)'!H31 -> 1000 | I31: ='상담(여)'!I31 -> 920 | J31: ='상담(여)'!J31 -> 897 | K31: ='상담(여)'!K31 -> 40 | L31: ='상담(여)'!L31 -> 40 | M31: ='상담(여)'!M31 -> 55 | N31: ='상담(여)'!N31 -> 60 | ... U31: ='상담(여)'!U31 -> .
A32: ='상담(여)'!A32 -> 서울 | B32: ='상담(여)'!B32 -> 서경대 스포츠&테크놀러지 | C32: ='상담(여)'!C32 -> 0 | D32: ='상담(여)'!D32 -> 294 | E32: ='상담(여)'!E32 -> 281 | F32: =C32-D32 -> -294 | G32: ='상담(여)'!G32 -> 400 | H32: ='상담(여)'!H32 -> 400 | I32: ='상담(여)'!I32 -> 687.33 | J32: ='상담(여)'!J32 -> 680.67 | K32: ='상담(여)'!K32 -> 30 | L32: ='상담(여)'!L32 -> 30 | M32: ='상담(여)'!M32 -> 0 | N32: ='상담(여)'!N32 -> 0 | ... T32: ='상담(여)'!T32 -> 19.90
A33: ='상담(여)'!A33 -> 서울 | B33: ='상담(여)'!B33 -> 서울여대 스포츠운동과학 | C33: ='상담(여)'!C33 -> 600 | D33: ='상담(여)'!D33 -> 58 | E33: ='상담(여)'!E33 -> 55.49 | F33: =C33-D33 -> 542 | G33: ='상담(여)'!G33 -> 40 | H33: ='상담(여)'!H33 -> 640 | I33: ='상담(여)'!I33 -> 97.7 | J33: ='상담(여)'!J33 -> 95.49 | K33: ='상담(여)'!K33 -> 10 | L33: ='상담(여)'!L33 -> 10 | M33: ='상담(여)'!M33 -> 10 | N33: ='상담(여)'!N33 -> 10 | ... U33: ='상담(여)'!U33 -> .
A34: ='상담(여)'!A34 -> 충남 | B34: ='상담(여)'!B34 -> 서원대 체육교육 | C34: ='상담(여)'!C34 -> 600 | D34: ='상담(여)'!D34 -> 588 | E34: ='상담(여)'!E34 -> 576 | F34: =C34-D34 -> 12 | G34: ='상담(여)'!G34 -> 400 | H34: ='상담(여)'!H34 -> 1000 | I34: ='상담(여)'!I34 -> 981.6 | J34: ='상담(여)'!J34 -> 976 | K34: ='상담(여)'!K34 -> 28 | L34: ='상담(여)'!L34 -> 23 | M34: ='상담(여)'!M34 -> 23 | N34: ='상담(여)'!N34 -> 23 | ... U34: ='상담(여)'!U34 -> 실기기본점수 80점/실기변경/변별력 상승
A35: ='상담(여)'!A35 -> 충남 | B35: ='상담(여)'!B35 -> 서원대 레저스포츠 | C35: ='상담(여)'!C35 -> 185 | D35: ='상담(여)'!D35 -> 190.5 | E35: ='상담(여)'!E35 -> 170 | F35: =C35-D35 -> -5.5 | G35: ='상담(여)'!G35 -> 800 | H35: ='상담(여)'!H35 -> 985 | I35: ='상담(여)'!I35 -> 978.3 | J35: ='상담(여)'!J35 -> 963.6 | K35: ='상담(여)'!K35 -> 31 | L35: ='상담(여)'!L35 -> 48 | M35: ='상담(여)'!M35 -> 45 | N35: ='상담(여)'!N35 -> 58 | ... U35: ='상담(여)'!U35 -> 실기기본점수 160점/변별력 상승
A36: ='상담(여)'!A36 -> 충남 | B36: ='상담(여)'!B36 -> 서원대 헬스케어운동 | C36: ='상담(여)'!C36 -> 165 | D36: ='상담(여)'!D36 -> 193 | E36: ='상담(여)'!E36 -> 175 | F36: =C36-D36 -> -28 | G36: ='상담(여)'!G36 -> 800 | H36: ='상담(여)'!H36 -> 965 | I36: ='상담(여)'!I36 -> 986.6 | J36: ='상담(여)'!J36 -> 971.4 | K36: ='상담(여)'!K36 -> 25 | L36: ='상담(여)'!L36 -> 25 | M36: ='상담(여)'!M36 -> 25 | N36: ='상담(여)'!N36 -> 30 | ... U36: ='상담(여)'!U36 -> 실기기본점수 160점/변별력 상승
A37: ='상담(여)'!A37 -> 충남 | B37: ='상담(여)'!B37 -> 선문대 스포츠과학 | C37: ='상담(여)'!C37 -> 180 | D37: ='상담(여)'!D37 -> 120 | E37: ='상담(여)'!E37 -> 40 | F37: =C37-D37 -> 60 | G37: ='상담(여)'!G37 -> 800 | H37: ='상담(여)'!H37 -> 980 | I37: ='상담(여)'!I37 -> 830 | J37: ='상담(여)'!J37 -> 795 | K37: ='상담(여)'!K37 -> 27 | L37: ='상담(여)'!L37 -> 26 | M37: ='상담(여)'!M37 -> 24 | N37: ='상담(여)'!N37 -> 25 | ... U37: ='상담(여)'!U37 -> .
A38: ='상담(여)'!A38 -> 충남 | B38: ='상담(여)'!B38 -> 선문대 피트니스재활 | C38: ='상담(여)'!C38 -> 170 | D38: ='상담(여)'!D38 -> 120 | E38: ='상담(여)'!E38 -> 40 | F38: =C38-D38 -> 50 | G38: ='상담(여)'!G38 -> 800 | H38: ='상담(여)'!H38 -> 970 | I38: ='상담(여)'!I38 -> 780 | J38: ='상담(여)'!J38 -> 734 | K38: ='상담(여)'!K38 -> 27 | L38: ='상담(여)'!L38 -> 25 | M38: ='상담(여)'!M38 -> 24 | N38: ='상담(여)'!N38 -> 25 | ... U38: ='상담(여)'!U38 -> .
A39: ='상담(여)'!A39 -> 경기 | B39: ='상담(여)'!B39 -> 성결대 체육교육 | C39: ='상담(여)'!C39 -> 400 | D39: ='상담(여)'!D39 -> 395 | E39: ='상담(여)'!E39 -> 385 | F39: =C39-D39 -> 5 | G39: ='상담(여)'!G39 -> 600 | H39: ='상담(여)'!H39 -> 1000 | I39: ='상담(여)'!I39 -> 991 | J39: ='상담(여)'!J39 -> 985 | K39: ='상담(여)'!K39 -> 14 | L39: ='상담(여)'!L39 -> 14 | M39: ='상담(여)'!M39 -> 14 | N39: ='상담(여)'!N39 -> 8 | ... U39: ='상담(여)'!U39 -> 내신반영방법 변경/교과점수 상승
A40: ='상담(여)'!A40 -> 충북 | B40: ='상담(여)'!B40 -> 세명대 생활체육 | C40: ='상담(여)'!C40 -> 200 | D40: ='상담(여)'!D40 -> 120 | E40: ='상담(여)'!E40 -> 40 | F40: =C40-D40 -> 80 | G40: ='상담(여)'!G40 -> 800 | H40: ='상담(여)'!H40 -> 1000 | I40: ='상담(여)'!I40 -> 860 | J40: ='상담(여)'!J40 -> 740 | K40: ='상담(여)'!K40 -> 30 | L40: ='상담(여)'!L40 -> 25 | M40: ='상담(여)'!M40 -> 25 | N40: ='상담(여)'!N40 -> 25 | ... U40: ='상담(여)'!U40 -> 윗몸폐지 농구신설 실기반영비율 증가
A41: ='상담(여)'!A41 -> 경기 | B41: ='상담(여)'!B41 -> 수원대 스포츠과학부 | C41: ='상담(여)'!C41 -> 400 | D41: ='상담(여)'!D41 -> 380 | E41: ='상담(여)'!E41 -> 367 | F41: =C41-D41 -> 20 | G41: ='상담(여)'!G41 -> 600 | H41: ='상담(여)'!H41 -> 1000 | I41: ='상담(여)'!I41 -> 974 | J41: ='상담(여)'!J41 -> 967 | K41: ='상담(여)'!K41 -> 기초 20 축구 13 농구 7 체조 5 | L41: ='상담(여)'!L41 -> 기초 20 축구 13 농구 7 체조 5 | M41: ='상담(여)'!M41 -> 20 | N41: ='상담(여)'!N41 -> 20 | ... U41: ='상담(여)'!U41 -> 기초체력 기준
A42: ='상담(여)'!A42 -> 서울 | B42: ='상담(여)'!B42 -> 숙명여대 체육교육 | C42: ='상담(여)'!C42 -> 400 | D42: ='상담(여)'!D42 -> 380 | E42: ='상담(여)'!E42 -> 354 | F42: =C42-D42 -> 20 | G42: ='상담(여)'!G42 -> 90 | H42: ='상담(여)'!H42 -> 490 | I42: ='상담(여)'!I42 -> 0 | J42: ='상담(여)'!J42 -> 0 | K42: ='상담(여)'!K42 -> 6 | L42: ='상담(여)'!L42 -> 6 | M42: ='상담(여)'!M42 -> 6 | N42: ='상담(여)'!N42 -> 5 | ... U42: ='상담(여)'!U42 -> 2등급 극초반까지 지원 고려
...

Sheet 상담(남)
C2: 상담학생 | E2: ='학생상담(남)'!E2 -> 황규훈
A4: 지역 | B4: 대학명 | C4: 내신환산점수 | D4: 합격자 평균점수 | E4: 실기상위권 지원점수 | F4: 내신환산점 과부족 | G4: 내실기점수 | H4: 내총점수 | I4: 안정점수 | J4: 기대점수 | K4: 2026 모집정원 | L4: 2025 모집정원 | M4: 2024 모집정원 | N4: 2023 모집정원 | O4: 2025 충원합격 | P4: 2024 충원합격 | Q4: 2023 충원합격 | R4: 2022 충원합격 | S4: 2025 경쟁률 | T4: 2024 경쟁률 | U4: 참고사항
A5: 경기 | B5: =대학별점수!B3 -> 가천대 체육 | C5: ='내신(남)'!B4 -> 300 | D5: =VLOOKUP(B5,대학별점수!$B$3:$C$74,2,FALSE) -> 294 | E5: =VLOOKUP(B5,대학별점수!$B$3:$D$74,3,FALSE) -> 273 | F5: =C5-D5 -> 6 | G5: ='실기환산(남)'!C2 -> 700 | H5: =C5+G5 -> 1000 | I5: =VLOOKUP(B5,대학별점수!$B$3:$M$74,4,0) -> 984 | J5: =VLOOKUP(B5,대학별점수!$B$3:$M$74,5,0) -> 973 | K5: =VLOOKUP(B5,대학별점수!$B$3:$T$73,6,0) -> 40 | L5: =VLOOKUP(B5,대학별점수!$B$3:$M$74,7,0) -> 40 | M5: =VLOOKUP(B5,대학별점수!$B$3:$M$74,8,0) -> 30 | N5: =VLOOKUP(B5,대학별점수!$B$3:$M$74,9,0) -> 20 | O5: =VLOOKUP(B5,대학별점수!$B$3:$T$73,19,0) -> 20 | P5: =VLOOKUP(B5,대학별점수!$B$3:$V$74,18,0) -> 37 | Q5: =VLOOKUP(B5,대학별점수!$B$3:$V$74,17,0) -> 3 | R5: =VLOOKUP(B5,대학별점수!$B$3:$V$74,16,0) -> 3 | S5: =VLOOKUP(B5,대학별점수!$B$3:$V$74,20,0) -> 49.18 | T5: =VLOOKUP(B5,대학별점수!$B$3:$V$74,21,0) -> 66.7 | U5: .
A6: 강원 | B6: =대학별점수!B4 -> 가톨릭관동대 체육교육 | C6: ='내신(남)'!B5 -> 700 | D6: =VLOOKUP(B6,대학별점수!$B$3:$C$74,2,FALSE) -> 661 | E6: =VLOOKUP(B6,대학별점수!$B$3:$D$74,3,FALSE) -> 621 | F6: =C6-D6 -> 39 | G6: ='실기환산(남)'!D2 -> 300 | H6: =C6+G6 -> 1000 | I6: =VLOOKUP(B6,대학별점수!$B$3:$M$74,4,0) -> 945 | J6: =VLOOKUP(B6,대학별점수!$B$3:$M$74,5,0) -> 921 | K6: =VLOOKUP(B6,대학별점수!$B$3:$T$73,6,0) -> 20 | L6: =VLOOKUP(B6,대학별점수!$B$3:$M$74,7,0) -> 20 | M6: =VLOOKUP(B6,대학별점수!$B$3:$M$74,8,0) -> 20 | N6: =VLOOKUP(B6,대학별점수!$B$3:$M$74,9,0) -> 20 | O6: =VLOOKUP(B6,대학별점수!$B$3:$T$73,19,0) -> 20 | P6: =VLOOKUP(B6,대학별점수!$B$3:$V$74,18,0) -> 27 | Q6: =VLOOKUP(B6,대학별점수!$B$3:$V$74,17,0) -> 32 | R6: =VLOOKUP(B6,대학별점수!$B$3:$V$74,16,0) -> 34 | S6: =VLOOKUP(B6,대학별점수!$B$3:$V$74,20,0) -> 8.05 | T6: =VLOOKUP(B6,대학별점수!$B$3:$V$74,21,0) -> 6.45 | U6: 내신8과목에서 12과목 반영
A7: 강원 | B7: =대학별점수!B5 -> 가톨릭관동대 스포츠레저 | C7: ='내신(남)'!B6 -> 600 | D7: =VLOOKUP(B7,대학별점수!$B$3:$C$74,2,FALSE) -> 485 | E7: =VLOOKUP(B7,대학별점수!$B$3:$D$74,3,FALSE) -> 414 | F7: =C7-D7 -> 115 | G7: ='실기환산(남)'!E2 -> 400 | H7: =C7+G7 -> 1000 | I7: =VLOOKUP(B7,대학별점수!$B$3:$M$74,4,0) -> 835 | J7: =VLOOKUP(B7,대학별점수!$B$3:$M$74,5,0) -> 814 | K7: =VLOOKUP(B7,대학별점수!$B$3:$T$73,6,0) -> 41 | L7: =VLOOKUP(B7,대학별점수!$B$3:$M$74,7,0) -> 40 | M7: =VLOOKUP(B7,대학별점수!$B$3:$M$74,8,0) -> 40 | N7: =VLOOKUP(B7,대학별점수!$B$3:$M$74,9,0) -> 96 | O7: =VLOOKUP(B7,대학별점수!$B$3:$T$73,19,0) -> 59 | P7: =VLOOKUP(B7,대학별점수!$B$3:$V$74,18,0) -> 7 | Q7: =VLOOKUP(B7,대학별점수!$B$3:$V$74,17,0) -> _ | R7: =VLOOKUP(B7,대학별점수!$B$3:$V$74,16,0) -> 64 | S7: =VLOOKUP(B7,대학별점수!$B$3:$V$74,20,0) -> 2.68 | T7: =VLOOKUP(B7,대학별점수!$B$3:$V$74,21,0) -> 1.3 | U7: 내신8과목에서 12과목 반영
A8: 강원 | B8: =대학별점수!B6 -> 가톨릭관동대 스포츠재활의학 | C8: ='내신(남)'!B7 -> 600 | D8: =VLOOKUP(B8,대학별점수!$B$3:$C$74,2,FALSE) -> 500 | E8: =VLOOKUP(B8,대학별점수!$B$3:$D$74,3,FALSE) -> 455 | F8: =C8-D8 -> 100 | G8: ='실기환산(남)'!F2 -> 400 | H8: =C8+G8 -> 1000 | I8: =VLOOKUP(B8,대학별점수!$B$3:$M$74,4,0) -> 878 | J8: =VLOOKUP(B8,대학별점수!$B$3:$M$74,5,0) -> 855 | K8: =VLOOKUP(B8,대학별점수!$B$3:$T$73,6,0) -> 40 | L8: =VLOOKUP(B8,대학별점수!$B$3:$M$74,7,0) -> 40 | M8: =VLOOKUP(B8,대학별점수!$B$3:$M$74,8,0) -> 31 | N8: =VLOOKUP(B8,대학별점수!$B$3:$M$74,9,0) -> 0 | O8: =VLOOKUP(B8,대학별점수!$B$3:$T$73,19,0) -> 46 | P8: =VLOOKUP(B8,대학별점수!$B$3:$V$74,18,0) -> 49 | Q8: =VLOOKUP(B8,대학별점수!$B$3:$V$74,17,0) -> _ | R8: =VLOOKUP(B8,대학별점수!$B$3:$V$74,16,0) -> 57 | S8: =VLOOKUP(B8,대학별점수!$B$3:$V$74,20,0) -> 5.28 | T8: =VLOOKUP(B8,대학별점수!$B$3:$V$74,21,0) -> 3.6 | U8: 실기만점기준 상향 조정
A9: 경기 | B9: =대학별점수!B7 -> 강남대 체육 | C9: ='내신(남)'!B8 -> 300 | D9: =VLOOKUP(B9,대학별점수!$B$3:$C$74,2,FALSE) -> 291 | E9: =VLOOKUP(B9,대학별점수!$B$3:$D$74,3,FALSE) -> 271 | F9: =C9-D9 -> 9 | G9: ='실기환산(남)'!G2 -> 676 | H9: =C9+G9 -> 976 | I9: =VLOOKUP(B9,대학별점수!$B$3:$M$74,4,0) -> 979 | J9: =VLOOKUP(B9,대학별점수!$B$3:$M$74,5,0) -> 971 | K9: =VLOOKUP(B9,대학별점수!$B$3:$T$73,6,0) -> 29 | L9: =VLOOKUP(B9,대학별점수!$B$3:$M$74,7,0) -> 29 | M9: =VLOOKUP(B9,대학별점수!$B$3:$M$74,8,0) -> 29 | N9: =VLOOKUP(B9,대학별점수!$B$3:$M$74,9,0) -> 29 | O9: =VLOOKUP(B9,대학별점수!$B$3:$T$73,19,0) -> 36 | P9: =VLOOKUP(B9,대학별점수!$B$3:$V$74,18,0) -> 38 | Q9: =VLOOKUP(B9,대학별점수!$B$3:$V$74,17,0) -> 38 | R9: =VLOOKUP(B9,대학별점수!$B$3:$V$74,16,0) -> 19 | S9: =VLOOKUP(B9,대학별점수!$B$3:$V$74,20,0) -> 23.62 | T9: =VLOOKUP(B9,대학별점수!$B$3:$V$74,21,0) -> 16.79 | U9: 내신반영변경,실기급간점수 변경
A10: 충북 | B10: =대학별점수!B8 -> 건국대(글) 스포츠건강 | C10: ='내신(남)'!B9 -> 200 | D10: =VLOOKUP(B10,대학별점수!$B$3:$C$74,2,FALSE) -> 165 | E10: =VLOOKUP(B10,대학별점수!$B$3:$D$74,3,FALSE) -> 121 | F10: =C10-D10 -> 35 | G10: ='실기환산(남)'!H2 -> 520 | H10: =C10+G10 -> 720 | I10: =VLOOKUP(B10,대학별점수!$B$3:$M$74,4,0) -> 951 | J10: =VLOOKUP(B10,대학별점수!$B$3:$M$74,5,0) -> 921 | K10: =VLOOKUP(B10,대학별점수!$B$3:$T$73,6,0) -> 20 | L10: =VLOOKUP(B10,대학별점수!$B$3:$M$74,7,0) -> 20 | M10: =VLOOKUP(B10,대학별점수!$B$3:$M$74,8,0) -> 22 | N10: =VLOOKUP(B10,대학별점수!$B$3:$M$74,9,0) -> 18 | O10: =VLOOKUP(B10,대학별점수!$B$3:$T$73,19,0) -> 15 | P10: =VLOOKUP(B10,대학별점수!$B$3:$V$74,18,0) -> 15 | Q10: =VLOOKUP(B10,대학별점수!$B$3:$V$74,17,0) -> 9 | R10: =VLOOKUP(B10,대학별점수!$B$3:$V$74,16,0) -> 8 | S10: =VLOOKUP(B10,대학별점수!$B$3:$V$74,20,0) -> 28.35 | T10: =VLOOKUP(B10,대학별점수!$B$3:$V$74,21,0) -> 17.09 | U10: 여자제멀, 남녀 농구 만점상향 조정
A11: 경기 | B11: =대학별점수!B9 -> 경기대 스포츠과학 | C11: ='내신(남)'!B10 -> 39 | D11: =VLOOKUP(B11,대학별점수!$B$3:$C$74,2,FALSE) -> 29.49 | E11: =VLOOKUP(B11,대학별점수!$B$3:$D$74,3,FALSE) -> 29.17 | F11: =C11-D11 -> 9.51 | G11: ='실기환산(남)'!I2 -> 70 | H11: =C11+G11 -> 109 | I11: =VLOOKUP(B11,대학별점수!$B$3:$M$74,4,0) -> 99.3 | J11: =VLOOKUP(B11,대학별점수!$B$3:$M$74,5,0) -> 99.17 | K11: =VLOOKUP(B11,대학별점수!$B$3:$T$73,6,0) -> 19 | L11: =VLOOKUP(B11,대학별점수!$B$3:$M$74,7,0) -> 10 | M11: =VLOOKUP(B11,대학별점수!$B$3:$M$74,8,0) -> 10 | N11: =VLOOKUP(B11,대학별점수!$B$3:$M$74,9,0) -> 10 | O11: =VLOOKUP(B11,대학별점수!$B$3:$T$73,19,0) -> 13 | P11: =VLOOKUP(B11,대학별점수!$B$3:$V$74,18,0) -> 4 | Q11: =VLOOKUP(B11,대학별점수!$B$3:$V$74,17,0) -> 15 | R11: =VLOOKUP(B11,대학별점수!$B$3:$V$74,16,0) -> 23신설 | S11: =VLOOKUP(B11,대학별점수!$B$3:$V$74,20,0) -> 62.00 | T11: =VLOOKUP(B11,대학별점수!$B$3:$V$74,21,0) -> 20.1 | U11: 만점기준 강화 실기반영(10%) 증가
A12: 경기 | B12: =대학별점수!B10 -> 경기대 체육 | C12: ='내신(남)'!B11 -> 39 | D12: =VLOOKUP(B12,대학별점수!$B$3:$C$74,2,FALSE) -> 0 | E12: =VLOOKUP(B12,대학별점수!$B$3:$D$74,3,FALSE) -> 0 | F12: =C12-D12 -> 39 | G12: ='실기환산(남)'!J2 -> 60 | H12: =C12+G12 -> 99 | I12: =VLOOKUP(B12,대학별점수!$B$3:$M$74,4,0) -> 0 | J12: =VLOOKUP(B12,대학별점수!$B$3:$M$74,5,0) -> 0 | K12: =VLOOKUP(B12,대학별점수!$B$3:$T$73,6,0) -> 미선발 | L12: =VLOOKUP(B12,대학별점수!$B$3:$M$74,7,0) -> 0 | M12: =VLOOKUP(B12,대학별점수!$B$3:$M$74,8,0) -> 5 | N12: =VLOOKUP(B12,대학별점수!$B$3:$M$74,9,0) -> 5 | O12: =VLOOKUP(B12,대학별점수!$B$3:$T$73,19,0) -> 미선발 | P12: =VLOOKUP(B12,대학별점수!$B$3:$V$74,18,0) -> 3 | Q12: =VLOOKUP(B12,대학별점수!$B$3:$V$74,17,0) -> 3 | R12: =VLOOKUP(B12,대학별점수!$B$3:$V$74,16,0) -> 23신설 | S12: =VLOOKUP(B12,대학별점수!$B$3:$V$74,20,0) -> 0 | T12: =VLOOKUP(B12,대학별점수!$B$3:$V$74,21,0) -> 9.0 | U12: 수시 폐지 2027 모집정원 전원 수시선발
A13: 충북 | B13: =대학별점수!B11 -> 극동대 스포츠재활 | C13: ='내신(남)'!B12 -> 200 | D13: =VLOOKUP(B13,대학별점수!$B$3:$C$74,2,FALSE) -> 160 | E13: =VLOOKUP(B13,대학별점수!$B$3:$D$74,3,FALSE) -> 116 | F13: =C13-D13 -> 40 | G13: ='실기환산(남)'!K2 -> 800 | H13: =C13+G13 -> 1000 | I13: =VLOOKUP(B13,대학별점수!$B$3:$M$74,4,0) -> 920 | J13: =VLOOKUP(B13,대학별점수!$B$3:$M$74,5,0) -> 889.33 | K13: =VLOOKUP(B13,대학별점수!$B$3:$T$73,6,0) -> 29 | L13: =VLOOKUP(B13,대학별점수!$B$3:$M$74,7,0) -> 16 | M13: =VLOOKUP(B13,대학별점수!$B$3:$M$74,8,0) -> 26 | N13: =VLOOKUP(B13,대학별점수!$B$3:$M$74,9,0) -> 30 | O13: =VLOOKUP(B13,대학별점수!$B$3:$T$73,19,0) -> 1 | P13: =VLOOKUP(B13,대학별점수!$B$3:$V$74,18,0) -> 미달 | Q13: =VLOOKUP(B13,대학별점수!$B$3:$V$74,17,0) -> _ | R13: =VLOOKUP(B13,대학별점수!$B$3:$V$74,16,0) -> 12 | S13: =VLOOKUP(B13,대학별점수!$B$3:$V$74,20,0) -> 2.44 | T13: =VLOOKUP(B13,대학별점수!$B$3:$V$74,21,0) -> 0.92 | U13: 실기 4종목 중 3종목 반영/ 경쟁률에 따른 컷라인 예측 불가
A14: 충남 | B14: =대학별점수!B12 -> 나사렛대 재활스포츠 | C14: ='내신(남)'!B13 -> 100 | D14: =VLOOKUP(B14,대학별점수!$B$3:$C$74,2,FALSE) -> 85 | E14: =VLOOKUP(B14,대학별점수!$B$3:$D$74,3,FALSE) -> 72 | F14: =C14-D14 -> 15 | G14: ='실기환산(남)'!L2 -> 900 | H14: =C14+G14 -> 1000 | I14: =VLOOKUP(B14,대학별점수!$B$3:$M$74,4,0) -> 965 | J14: =VLOOKUP(B14,대학별점수!$B$3:$M$74,5,0) -> 923 | K14: =VLOOKUP(B14,대학별점수!$B$3:$T$73,6,0) -> 55 | L14: =VLOOKUP(B14,대학별점수!$B$3:$M$74,7,0) -> 30 | M14: =VLOOKUP(B14,대학별점수!$B$3:$M$74,8,0) -> 30 | N14: =VLOOKUP(B14,대학별점수!$B$3:$M$74,9,0) -> 30 | O14: =VLOOKUP(B14,대학별점수!$B$3:$T$73,19,0) -> 39 | P14: =VLOOKUP(B14,대학별점수!$B$3:$V$74,18,0) -> 48 | Q14: =VLOOKUP(B14,대학별점수!$B$3:$V$74,17,0) -> 26 | R14: =VLOOKUP(B14,대학별점수!$B$3:$V$74,16,0) -> 17 | S14: =VLOOKUP(B14,대학별점수!$B$3:$V$74,20,0) -> 13.20 | T14: =VLOOKUP(B14,대학별점수!$B$3:$V$74,21,0) -> 12.67 | U14: 모집정원 대폭증가 컷라인 내려가라~
A15: 충남 | B15: =대학별점수!B13 -> 남서울대 스포츠건강관리 | C15: ='내신(남)'!B14 -> 258 | D15: =VLOOKUP(B15,대학별점수!$B$3:$C$74,2,FALSE) -> 210 | E15: =VLOOKUP(B15,대학별점수!$B$3:$D$74,3,FALSE) -> 154 | F15: =C15-D15 -> 48 | G15: ='실기환산(남)'!M2 -> 700 | H15: =C15+G15 -> 958 | I15: =VLOOKUP(B15,대학별점수!$B$3:$M$74,4,0) -> 851 | J15: =VLOOKUP(B15,대학별점수!$B$3:$M$74,5,0) -> 805 | K15: =VLOOKUP(B15,대학별점수!$B$3:$T$73,6,0) -> 42 | L15: =VLOOKUP(B15,대학별점수!$B$3:$M$74,7,0) -> 41 | M15: =VLOOKUP(B15,대학별점수!$B$3:$M$74,8,0) -> 36 | N15: =VLOOKUP(B15,대학별점수!$B$3:$M$74,9,0) -> 38 | O15: =VLOOKUP(B15,대학별점수!$B$3:$T$73,19,0) -> 52 | P15: =VLOOKUP(B15,대학별점수!$B$3:$V$74,18,0) -> 86 | Q15: =VLOOKUP(B15,대학별점수!$B$3:$V$74,17,0) -> 100 | R15: =VLOOKUP(B15,대학별점수!$B$3:$V$74,16,0) -> 48 | S15: =VLOOKUP(B15,대학별점수!$B$3:$V$74,20,0) -> 7.76 | T15: =VLOOKUP(B15,대학별점수!$B$3:$V$74,21,0) -> 6.22 | U15: 좌전굴 폐지 매던 신설
A16: 충남 | B16: =대학별점수!B14 -> 남서울대 스포츠비즈니스 | C16: ='내신(남)'!B15 -> 249 | D16: =VLOOKUP(B16,대학별점수!$B$3:$C$74,2,FALSE) -> 210 | E16: =VLOOKUP(B16,대학별점수!$B$3:$D$74,3,FALSE) -> 136 | F16: =C16-D16 -> 39 | G16: ='실기환산(남)'!N2 -> 700 | H16: =C16+G16 -> 949 | I16: =VLOOKUP(B16,대학별점수!$B$3:$M$74,4,0) -> 840 | J16: =VLOOKUP(B16,대학별점수!$B$3:$M$74,5,0) -> 784 | K16: =VLOOKUP(B16,대학별점수!$B$3:$T$73,6,0) -> 42 | L16: =VLOOKUP(B16,대학별점수!$B$3:$M$74,7,0) -> 40 | M16: =VLOOKUP(B16,대학별점수!$B$3:$M$74,8,0) -> 35 | N16: =VLOOKUP(B16,대학별점수!$B$3:$M$74,9,0) -> 38 | O16: =VLOOKUP(B16,대학별점수!$B$3:$T$73,19,0) -> 37 | P16: =VLOOKUP(B16,대학별점수!$B$3:$V$74,18,0) -> 50 | Q16: =VLOOKUP(B16,대학별점수!$B$3:$V$74,17,0) -> 74 | R16: =VLOOKUP(B16,대학별점수!$B$3:$V$74,16,0) -> 43 | S16: =VLOOKUP(B16,대학별점수!$B$3:$V$74,20,0) -> 4.93 | T16: =VLOOKUP(B16,대학별점수!$B$3:$V$74,21,0) -> 4.74 | U16: 3종목 모두 반영으로 총점 하향???
A17: 경기 | B17: =대학별점수!B15 -> 단국대 체육교육 | C17: ='내신(남)'!B17 -> 198 | D17: =VLOOKUP(B17,대학별점수!$B$3:$C$74,2,FALSE) -> 686 | E17: =VLOOKUP(B17,대학별점수!$B$3:$D$74,3,FALSE) -> 668 | F17: =C17-D17 -> -488 | G17: ='실기환산(남)'!O2 -> 270 | H17: =C17+G17 -> 468 | I17: =VLOOKUP(B17,대학별점수!$B$3:$M$74,4,0) -> 982 | J17: =VLOOKUP(B17,대학별점수!$B$3:$M$74,5,0) -> 968 | K17: =VLOOKUP(B17,대학별점수!$B$3:$T$73,6,0) -> 10 | L17: =VLOOKUP(B17,대학별점수!$B$3:$M$74,7,0) -> 10 | M17: =VLOOKUP(B17,대학별점수!$B$3:$M$74,8,0) -> 0 | N17: =VLOOKUP(B17,대학별점수!$B$3:$M$74,9,0) -> 0 | O17: =VLOOKUP(B17,대학별점수!$B$3:$T$73,19,0) -> 2 | P17: =VLOOKUP(B17,대학별점수!$B$3:$V$74,18,0) -> 0 | Q17: =VLOOKUP(B17,대학별점수!$B$3:$V$74,17,0) -> 0 | R17: =VLOOKUP(B17,대학별점수!$B$3:$V$74,16,0) -> 0 | S17: =VLOOKUP(B17,대학별점수!$B$3:$V$74,20,0) -> 42.50 | T17: =VLOOKUP(B17,대학별점수!$B$3:$V$74,21,0) -> 0 | U17: 실기만점이면 도전해야죠
A18: 충남 | B18: =대학별점수!B16 -> 단국대 생활체육 | C18: ='내신(남)'!B17 -> 198 | D18: =VLOOKUP(B18,대학별점수!$B$3:$C$74,2,FALSE) -> 190 | E18: =VLOOKUP(B18,대학별점수!$B$3:$D$74,3,FALSE) -> 180 | F18: =C18-D18 -> 8 | G18: ='실기환산(남)'!P2 -> 800 | H18: =C18+G18 -> 998 | I18: =VLOOKUP(B18,대학별점수!$B$3:$M$74,4,0) -> 990 | J18: =VLOOKUP(B18,대학별점수!$B$3:$M$74,5,0) -> 980 | K18: =VLOOKUP(B18,대학별점수!$B$3:$T$73,6,0) -> 14 | L18: =VLOOKUP(B18,대학별점수!$B$3:$M$74,7,0) -> 14 | M18: =VLOOKUP(B18,대학별점수!$B$3:$M$74,8,0) -> 15 | N18: =VLOOKUP(B18,대학별점수!$B$3:$M$74,9,0) -> 15 | O18: =VLOOKUP(B18,대학별점수!$B$3:$T$73,19,0) -> 12 | P18: =VLOOKUP(B18,대학별점수!$B$3:$V$74,18,0) -> 8 | Q18: =VLOOKUP(B18,대학별점수!$B$3:$V$74,17,0) -> 3 | R18: =VLOOKUP(B18,대학별점수!$B$3:$V$74,16,0) -> 23신설 | S18: =VLOOKUP(B18,대학별점수!$B$3:$V$74,20,0) -> 42.36 | T18: =VLOOKUP(B18,대학별점수!$B$3:$V$74,21,0) -> 34.6 | U18: .
A19: 충남 | B19: =대학별점수!B17 -> 단국대 운동처방재활 | C19: ='내신(남)'!B18 -> 198 | D19: =VLOOKUP(B19,대학별점수!$B$3:$C$74,2,FALSE) -> 194.8 | E19: =VLOOKUP(B19,대학별점수!$B$3:$D$74,3,FALSE) -> 192.2 | F19: =C19-D19 -> 3.2 | G19: ='실기환산(남)'!Q2 -> 800 | H19: =C19+G19 -> 998 | I19: =VLOOKUP(B19,대학별점수!$B$3:$M$74,4,0) -> 0 | J19: =VLOOKUP(B19,대학별점수!$B$3:$M$74,5,0) -> 0 | K19: =VLOOKUP(B19,대학별점수!$B$3:$T$73,6,0) -> 미선발 | L19: =VLOOKUP(B19,대학별점수!$B$3:$M$74,7,0) -> 5 | M19: =VLOOKUP(B19,대학별점수!$B$3:$M$74,8,0) -> 5 | N19: =VLOOKUP(B19,대학별점수!$B$3:$M$74,9,0) -> 6 | O19: =VLOOKUP(B19,대학별점수!$B$3:$T$73,19,0) -> 5 | P19: =VLOOKUP(B19,대학별점수!$B$3:$V$74,18,0) -> 4 | Q19: =VLOOKUP(B19,대학별점수!$B$3:$V$74,17,0) -> 1 | R19: =VLOOKUP(B19,대학별점수!$B$3:$V$74,16,0) -> 23신설 | S19: =VLOOKUP(B19,대학별점수!$B$3:$V$74,20,0) -> 36.20 | T19: =VLOOKUP(B19,대학별점수!$B$3:$V$74,21,0) -> 27.4 | U19: 실기전형 미선발/교과전형 선발
A20: 대전 | B20: =대학별점수!B18 -> 대전대 스포츠건강재활 | C20: ='내신(남)'!B19 -> 400 | D20: =VLOOKUP(B20,대학별점수!$B$3:$C$74,2,FALSE) -> 352 | E20: =VLOOKUP(B20,대학별점수!$B$3:$D$74,3,FALSE) -> 330 | F20: =C20-D20 -> 48 | G20: ='실기환산(남)'!R2 -> 585 | H20: =C20+G20 -> 985 | I20: =VLOOKUP(B20,대학별점수!$B$3:$M$74,4,0) -> 942 | J20: =VLOOKUP(B20,대학별점수!$B$3:$M$74,5,0) -> 930 | K20: =VLOOKUP(B20,대학별점수!$B$3:$T$73,6,0) -> 27 | L20: =VLOOKUP(B20,대학별점수!$B$3:$M$74,7,0) -> 25 | M20: =VLOOKUP(B20,대학별점수!$B$3:$M$74,8,0) -> 25 | N20: =VLOOKUP(B20,대학별점수!$B$3:$M$74,9,0) -> 25 | O20: =VLOOKUP(B20,대학별점수!$B$3:$T$73,19,0) -> 28 | P20: =VLOOKUP(B20,대학별점수!$B$3:$V$74,18,0) -> 37 | Q20: =VLOOKUP(B20,대학별점수!$B$3:$V$74,17,0) -> 54 | R20: =VLOOKUP(B20,대학별점수!$B$3:$V$74,16,0) -> 42 | S20: =VLOOKUP(B20,대학별점수!$B$3:$V$74,20,0) -> 8.88 | T20: =VLOOKUP(B20,대학별점수!$B$3:$V$74,21,0) -> 7.96 | U20: .
A21: 대전 | B21: =대학별점수!B19 -> 대전대 스포츠운동과학 | C21: ='내신(남)'!B20 -> 400 | D21: =VLOOKUP(B21,대학별점수!$B$3:$C$74,2,FALSE) -> 348 | E21: =VLOOKUP(B21,대학별점수!$B$3:$D$74,3,FALSE) -> 320 | F21: =C21-D21 -> 52 | G21: ='실기환산(남)'!S2 -> 585 | H21: =C21+G21 -> 985 | I21: =VLOOKUP(B21,대학별점수!$B$3:$M$74,4,0) -> 938 | J21: =VLOOKUP(B21,대학별점수!$B$3:$M$74,5,0) -> 920 | K21: =VLOOKUP(B21,대학별점수!$B$3:$T$73,6,0) -> 32 | L21: =VLOOKUP(B21,대학별점수!$B$3:$M$74,7,0) -> 32 | M21: =VLOOKUP(B21,대학별점수!$B$3:$M$74,8,0) -> 23 | N21: =VLOOKUP(B21,대학별점수!$B$3:$M$74,9,0) -> 20 | O21: =VLOOKUP(B21,대학별점수!$B$3:$T$73,19,0) -> 22 | P21: =VLOOKUP(B21,대학별점수!$B$3:$V$74,18,0) -> 35 | Q21: =VLOOKUP(B21,대학별점수!$B$3:$V$74,17,0) -> 30 | R21: =VLOOKUP(B21,대학별점수!$B$3:$V$74,16,0) -> 37 | S21: =VLOOKUP(B21,대학별점수!$B$3:$V$74,20,0) -> 3.81 | T21: =VLOOKUP(B21,대학별점수!$B$3:$V$74,21,0) -> 4.52 | U21: .
A22: 경기 | B22: =대학별점수!B20 -> 대진대 스포츠겅강과학 | C22: ='내신(남)'!B21 -> 200 | D22: =VLOOKUP(B22,대학별점수!$B$3:$C$74,2,FALSE) -> 184 | E22: =VLOOKUP(B22,대학별점수!$B$3:$D$74,3,FALSE) -> 179.3 | F22: =C22-D22 -> 16 | G22: ='실기환산(남)'!T2 -> 800 | H22: =C22+G22 -> 1000 | I22: =VLOOKUP(B22,대학별점수!$B$3:$M$74,4,0) -> 984 | J22: =VLOOKUP(B22,대학별점수!$B$3:$M$74,5,0) -> 979.3 | K22: =VLOOKUP(B22,대학별점수!$B$3:$T$73,6,0) -> 25 | L22: =VLOOKUP(B22,대학별점수!$B$3:$M$74,7,0) -> 25 | M22: =VLOOKUP(B22,대학별점수!$B$3:$M$74,8,0) -> 25 | N22: =VLOOKUP(B22,대학별점수!$B$3:$M$74,9,0) -> 22 | O22: =VLOOKUP(B22,대학별점수!$B$3:$T$73,19,0) -> 22 | P22: =VLOOKUP(B22,대학별점수!$B$3:$V$74,18,0) -> 32 | Q22: =VLOOKUP(B22,대학별점수!$B$3:$V$74,17,0) -> 33 | R22: =VLOOKUP(B22,대학별점수!$B$3:$V$74,16,0) -> 21 | S22: =VLOOKUP(B22,대학별점수!$B$3:$V$74,20,0) -> 10.48 | T22: =VLOOKUP(B22,대학별점수!$B$3:$V$74,21,0) -> 6.88 | U22: 진로선택3과목 반영에서 5과목 반영
A23: 서울 | B23: =대학별점수!B21 -> 동국대 체육교육 | C23: ='내신(남)'!B22 -> 300 | D23: =VLOOKUP(B23,대학별점수!$B$3:$C$74,2,FALSE) -> 298.4 | E23: =VLOOKUP(B23,대학별점수!$B$3:$D$74,3,FALSE) -> 294.3 | F23: =C23-D23 -> 1.6 | G23: ='실기환산(남)'!U2 -> 700 | H23: =C23+G23 -> 1000 | I23: =VLOOKUP(B23,대학별점수!$B$3:$M$74,4,0) -> 996.5 | J23: =VLOOKUP(B23,대학별점수!$B$3:$M$74,5,0) -> 994.3 | K23: =VLOOKUP(B23,대학별점수!$B$3:$T$73,6,0) -> 22 | L23: =VLOOKUP(B23,대학별점수!$B$3:$M$74,7,0) -> 23 | M23: =VLOOKUP(B23,대학별점수!$B$3:$M$74,8,0) -> 23 | N23: =VLOOKUP(B23,대학별점수!$B$3:$M$74,9,0) -> 23 | O23: =VLOOKUP(B23,대학별점수!$B$3:$T$73,19,0) -> 0 | P23: =VLOOKUP(B23,대학별점수!$B$3:$V$74,18,0) -> 0 | Q23: =VLOOKUP(B23,대학별점수!$B$3:$V$74,17,0) -> 0 | R23: =VLOOKUP(B23,대학별점수!$B$3:$V$74,16,0) -> _ | S23: =VLOOKUP(B23,대학별점수!$B$3:$V$74,20,0) -> 30.17 | T23: =VLOOKUP(B23,대학별점수!$B$3:$V$74,21,0) -> 27.22 | U23: 실기기본점수 50점
A24: 대전 | B24: =대학별점수!B23 -> 목원대 스포츠건강관리 | C24: ='내신(남)'!B23 -> 92 | D24: =VLOOKUP(B24,대학별점수!$B$3:$C$74,2,FALSE) -> 86 | E24: =VLOOKUP(B24,대학별점수!$B$3:$D$74,3,FALSE) -> 50 | F24: =C24-D24 -> 6 | G24: ='실기환산(남)'!V2 -> 900 | H24: =C24+G24 -> 992 | I24: =VLOOKUP(B24,대학별점수!$B$3:$M$74,4,0) -> 918 | J24: =VLOOKUP(B24,대학별점수!$B$3:$M$74,5,0) -> 888 | K24: =VLOOKUP(B24,대학별점수!$B$3:$T$73,6,0) -> 30 | L24: =VLOOKUP(B24,대학별점수!$B$3:$M$74,7,0) -> 33 | M24: =VLOOKUP(B24,대학별점수!$B$3:$M$74,8,0) -> 33 | N24: =VLOOKUP(B24,대학별점수!$B$3:$M$74,9,0) -> 54 | O24: =VLOOKUP(B24,대학별점수!$B$3:$T$73,19,0) -> 76 | P24: =VLOOKUP(B24,대학별점수!$B$3:$V$74,18,0) -> 126 | Q24: =VLOOKUP(B24,대학별점수!$B$3:$V$74,17,0) -> 149 | R24: =VLOOKUP(B24,대학별점수!$B$3:$V$74,16,0) -> 129 | S24: =VLOOKUP(B24,대학별점수!$B$3:$V$74,20,0) -> 6.90 | T24: =VLOOKUP(B24,대학별점수!$B$3:$V$74,21,0) -> 5.73 | U24: .
A25: 충남 | B25: =대학별점수!B24 -> 백석대 특수체육교육 | C25: ='내신(남)'!B25 -> 400 | D25: =VLOOKUP(B25,대학별점수!$B$3:$C$74,2,FALSE) -> 552 | E25: =VLOOKUP(B25,대학별점수!$B$3:$D$74,3,FALSE) -> 516 | F25: =C25-D25 -> -152 | G25: ='실기환산(남)'!W2 -> 400 | H25: =C25+G25 -> 800 | I25: =VLOOKUP(B25,대학별점수!$B$3:$M$74,4,0) -> 930.67 | J25: =VLOOKUP(B25,대학별점수!$B$3:$M$74,5,0) -> 916 | K25: =VLOOKUP(B25,대학별점수!$B$3:$T$73,6,0) -> 27 | L25: =VLOOKUP(B25,대학별점수!$B$3:$M$74,7,0) -> 27 | M25: =VLOOKUP(B25,대학별점수!$B$3:$M$74,8,0) -> 27 | N25: =VLOOKUP(B25,대학별점수!$B$3:$M$74,9,0) -> 26 | O25: =VLOOKUP(B25,대학별점수!$B$3:$T$73,19,0) -> 16 | P25: =VLOOKUP(B25,대학별점수!$B$3:$V$74,18,0) -> 28 | Q25: =VLOOKUP(B25,대학별점수!$B$3:$V$74,17,0) -> 32 | R25: =VLOOKUP(B25,대학별점수!$B$3:$V$74,16,0) -> 16 | S25: =VLOOKUP(B25,대학별점수!$B$3:$V$74,20,0) -> 6.15 | T25: =VLOOKUP(B25,대학별점수!$B$3:$V$74,21,0) -> 5.15 | U25: .
A26: 충남 | B26: =대학별점수!B25 -> 백석대 스포츠과학 | C26: ='내신(남)'!B24 -> 600 | D26: =VLOOKUP(B26,대학별점수!$B$3:$C$74,2,FALSE) -> 349 | E26: =VLOOKUP(B26,대학별점수!$B$3:$D$74,3,FALSE) -> 323 | F26: =C26-D26 -> 251 | G26: ='실기환산(남)'!X2 -> 600 | H26: =C26+G26 -> 1200 | I26: =VLOOKUP(B26,대학별점수!$B$3:$M$74,4,0) -> 941 | J26: =VLOOKUP(B26,대학별점수!$B$3:$M$74,5,0) -> 923 | K26: =VLOOKUP(B26,대학별점수!$B$3:$T$73,6,0) -> 73 | L26: =VLOOKUP(B26,대학별점수!$B$3:$M$74,7,0) -> 73 | M26: =VLOOKUP(B26,대학별점수!$B$3:$M$74,8,0) -> 75 | N26: =VLOOKUP(B26,대학별점수!$B$3:$M$74,9,0) -> 46 | O26: =VLOOKUP(B26,대학별점수!$B$3:$T$73,19,0) -> 36 | P26: =VLOOKUP(B26,대학별점수!$B$3:$V$74,18,0) -> 42 | Q26: =VLOOKUP(B26,대학별점수!$B$3:$V$74,17,0) -> 30 | R26: =VLOOKUP(B26,대학별점수!$B$3:$V$74,16,0) -> 19 | S26: =VLOOKUP(B26,대학별점수!$B$3:$V$74,20,0) -> 10.96 | T26: =VLOOKUP(B26,대학별점수!$B$3:$V$74,21,0) -> 9.29 | U26: .
A27: 서울 | B27: =대학별점수!B26 -> 삼육대 체육 | C27: ='내신(남)'!B26 -> 400 | D27: =VLOOKUP(B27,대학별점수!$B$3:$C$74,2,FALSE) -> 392 | E27: =VLOOKUP(B27,대학별점수!$B$3:$D$74,3,FALSE) -> 386 | F27: =C27-D27 -> 8 | G27: ='실기환산(남)'!Y2 -> 600 | H27: =C27+G27 -> 1000 | I27: =VLOOKUP(B27,대학별점수!$B$3:$M$74,4,0) -> 990 | J27: =VLOOKUP(B27,대학별점수!$B$3:$M$74,5,0) -> 986 | K27: =VLOOKUP(B27,대학별점수!$B$3:$T$73,6,0) -> 12 | L27: =VLOOKUP(B27,대학별점수!$B$3:$M$74,7,0) -> 10 | M27: =VLOOKUP(B27,대학별점수!$B$3:$M$74,8,0) -> 11 | N27: =VLOOKUP(B27,대학별점수!$B$3:$M$74,9,0) -> 9 | O27: =VLOOKUP(B27,대학별점수!$B$3:$T$73,19,0) -> 4 | P27: =VLOOKUP(B27,대학별점수!$B$3:$V$74,18,0) -> 4 | Q27: =VLOOKUP(B27,대학별점수!$B$3:$V$74,17,0) -> 3 | R27: =VLOOKUP(B27,대학별점수!$B$3:$V$74,16,0) -> 14 | S27: =VLOOKUP(B27,대학별점수!$B$3:$V$74,20,0) -> 13.70 | T27: =VLOOKUP(B27,대학별점수!$B$3:$V$74,21,0) -> 29.91 | U27: 진로선택3과목 반영에서 이수전과목 반영
A28: 서울 | B28: =대학별점수!B27 -> 상명대 스포츠건강 | C28: ='내신(남)'!B27 -> 300 | D28: =VLOOKUP(B28,대학별점수!$B$3:$C$74,2,FALSE) -> 282 | E28: =VLOOKUP(B28,대학별점수!$B$3:$D$74,3,FALSE) -> 235 | F28: =C28-D28 -> 18 | G28: ='실기환산(남)'!Z2 -> 675.5 | H28: =C28+G28 -> 975.5 | I28: =VLOOKUP(B28,대학별점수!$B$3:$M$74,4,0) -> 961 | J28: =VLOOKUP(B28,대학별점수!$B$3:$M$74,5,0) -> 935 | K28: =VLOOKUP(B28,대학별점수!$B$3:$T$73,6,0) -> 12 | L28: =VLOOKUP(B28,대학별점수!$B$3:$M$74,7,0) -> 12 | M28: =VLOOKUP(B28,대학별점수!$B$3:$M$74,8,0) -> 0 | N28: =VLOOKUP(B28,대학별점수!$B$3:$M$74,9,0) -> 0 | O28: =VLOOKUP(B28,대학별점수!$B$3:$T$73,19,0) -> 12 | P28: =VLOOKUP(B28,대학별점수!$B$3:$V$74,18,0) -> 0 | Q28: =VLOOKUP(B28,대학별점수!$B$3:$V$74,17,0) -> 0 | R28: =VLOOKUP(B28,대학별점수!$B$3:$V$74,16,0) -> 0 | S28: =VLOOKUP(B28,대학별점수!$B$3:$V$74,20,0) -> 65.92 | T28: =VLOOKUP(B28,대학별점수!$B$3:$V$74,21,0) -> 0 | U28: 실기만점기준 상향 조정
A29: 충남 | B29: =대학별점수!B28 -> 상명대(천안) 스포츠융합 | C29: ='내신(남)'!B28 -> 400 | D29: =VLOOKUP(B29,대학별점수!$B$3:$C$74,2,FALSE) -> 357 | E29: =VLOOKUP(B29,대학별점수!$B$3:$D$74,3,FALSE) -> 288 | F29: =C29-D29 -> 43 | G29: ='실기환산(남)'!AA2 -> 590 | H29: =C29+G29 -> 990 | I29: =VLOOKUP(B29,대학별점수!$B$3:$M$74,4,0) -> 910 | J29: =VLOOKUP(B29,대학별점수!$B$3:$M$74,5,0) -> 888 | K29: =VLOOKUP(B29,대학별점수!$B$3:$T$73,6,0) -> 38 | L29: =VLOOKUP(B29,대학별점수!$B$3:$M$74,7,0) -> 38 | M29: =VLOOKUP(B29,대학별점수!$B$3:$M$74,8,0) -> 38 | N29: =VLOOKUP(B29,대학별점수!$B$3:$M$74,9,0) -> 43 | O29: =VLOOKUP(B29,대학별점수!$B$3:$T$73,19,0) -> 23 | P29: =VLOOKUP(B29,대학별점수!$B$3:$V$74,18,0) -> 37 | Q29: =VLOOKUP(B29,대학별점수!$B$3:$V$74,17,0) -> 27 | R29: =VLOOKUP(B29,대학별점수!$B$3:$V$74,16,0) -> 33 | S29: =VLOOKUP(B29,대학별점수!$B$3:$V$74,20,0) -> 7.68 | T29: =VLOOKUP(B29,대학별점수!$B$3:$V$74,21,0) -> 7.9 | U29: .
A30: 강원 | B30: =대학별점수!B29 -> 상지대 체육 | C30: ='내신(남)'!B29 -> 300 | D30: =VLOOKUP(B30,대학별점수!$B$3:$C$74,2,FALSE) -> 233 | E30: =VLOOKUP(B30,대학별점수!$B$3:$D$74,3,FALSE) -> 197 | F30: =C30-D30 -> 67 | G30: ='실기환산(남)'!AB2 -> 700 | H30: =C30+G30 -> 1000 | I30: =VLOOKUP(B30,대학별점수!$B$3:$M$74,4,0) -> 920 | J30: =VLOOKUP(B30,대학별점수!$B$3:$M$74,5,0) -> 897 | K30: =VLOOKUP(B30,대학별점수!$B$3:$T$73,6,0) -> 40 | L30: =VLOOKUP(B30,대학별점수!$B$3:$M$74,7,0) -> 40 | M30: =VLOOKUP(B30,대학별점수!$B$3:$M$74,8,0) -> 55 | N30: =VLOOKUP(B30,대학별점수!$B$3:$M$74,9,0) -> 60 | O30: =VLOOKUP(B30,대학별점수!$B$3:$T$73,19,0) -> 56 | P30: =VLOOKUP(B30,대학별점수!$B$3:$V$74,18,0) -> 40 | Q30: =VLOOKUP(B30,대학별점수!$B$3:$V$74,17,0) -> 24 | R30: =VLOOKUP(B30,대학별점수!$B$3:$V$74,16,0) -> 47 | S30: =VLOOKUP(B30,대학별점수!$B$3:$V$74,20,0) -> 4.28 | T30: =VLOOKUP(B30,대학별점수!$B$3:$V$74,21,0) -> 1.93 | U30: .
A31: 서울 | B31: =대학별점수!B30 -> 서경대 스포츠&테크놀러지 | C31: ='내신(남)'!B30 -> 250 | D31: =VLOOKUP(B31,대학별점수!$B$3:$C$74,2,FALSE) -> 294 | E31: =VLOOKUP(B31,대학별점수!$B$3:$D$74,3,FALSE) -> 281 | F31: =C31-D31 -> -44 | G31: ='실기환산(남)'!AC2 -> 400 | H31: =C31+G31 -> 650 | I31: =VLOOKUP(B31,대학별점수!$B$3:$M$74,4,0) -> 687.33 | J31: =VLOOKUP(B31,대학별점수!$B$3:$M$74,5,0) -> 680.67 | K31: =VLOOKUP(B31,대학별점수!$B$3:$T$73,6,0) -> 30 | L31: =VLOOKUP(B31,대학별점수!$B$3:$M$74,7,0) -> 30 | M31: =VLOOKUP(B31,대학별점수!$B$3:$M$74,8,0) -> 0 | N31: =VLOOKUP(B31,대학별점수!$B$3:$M$74,9,0) -> 0 | O31: =VLOOKUP(B31,대학별점수!$B$3:$T$73,19,0) -> 2 | P31: =VLOOKUP(B31,대학별점수!$B$3:$V$74,18,0) -> 7 | Q31: =VLOOKUP(B31,대학별점수!$B$3:$V$74,17,0) -> 0 | R31: =VLOOKUP(B31,대학별점수!$B$3:$V$74,16,0) -> 0 | S31: =VLOOKUP(B31,대학별점수!$B$3:$V$74,20,0) -> 24.70 | T31: =VLOOKUP(B31,대학별점수!$B$3:$V$74,21,0) -> 19.90 | U31: .
A32: 충남 | B32: =대학별점수!B32 -> 서원대 체육교육 | C32: ='내신(남)'!B31 -> 600 | D32: =VLOOKUP(B32,대학별점수!$B$3:$C$74,2,FALSE) -> 588 | E32: =VLOOKUP(B32,대학별점수!$B$3:$D$74,3,FALSE) -> 576 | F32: =C32-D32 -> 12 | G32: ='실기환산(남)'!AD2 -> 400 | H32: =C32+G32 -> 1000 | I32: =VLOOKUP(B32,대학별점수!$B$3:$M$74,4,0) -> 981.6 | J32: =VLOOKUP(B32,대학별점수!$B$3:$M$74,5,0) -> 976 | K32: =VLOOKUP(B32,대학별점수!$B$3:$T$73,6,0) -> 28 | L32: =VLOOKUP(B32,대학별점수!$B$3:$M$74,7,0) -> 23 | M32: =VLOOKUP(B32,대학별점수!$B$3:$M$74,8,0) -> 23 | N32: =VLOOKUP(B32,대학별점수!$B$3:$M$74,9,0) -> 23 | O32: =VLOOKUP(B32,대학별점수!$B$3:$T$73,19,0) -> 36 | P32: =VLOOKUP(B32,대학별점수!$B$3:$V$74,18,0) -> 23 | Q32: =VLOOKUP(B32,대학별점수!$B$3:$V$74,17,0) -> _ | R32: =VLOOKUP(B32,대학별점수!$B$3:$V$74,16,0) -> 13 | S32: =VLOOKUP(B32,대학별점수!$B$3:$V$74,20,0) -> 6.74 | T32: =VLOOKUP(B32,대학별점수!$B$3:$V$74,21,0) -> 11.52 | U32: 실기기본점수 80점/실기변경/변별력 상승
A33: 충남 | B33: =대학별점수!B33 -> 서원대 레저스포츠 | C33: ='내신(남)'!B32 -> 200 | D33: =VLOOKUP(B33,대학별점수!$B$3:$C$74,2,FALSE) -> 190.5 | E33: =VLOOKUP(B33,대학별점수!$B$3:$D$74,3,FALSE) -> 170 | F33: =C33-D33 -> 9.5 | G33: ='실기환산(남)'!AE2 -> 800 | H33: =C33+G33 -> 1000 | I33: =VLOOKUP(B33,대학별점수!$B$3:$M$74,4,0) -> 978.3 | J33: =VLOOKUP(B33,대학별점수!$B$3:$M$74,5,0) -> 963.6 | K33: =VLOOKUP(B33,대학별점수!$B$3:$T$73,6,0) -> 31 | L33: =VLOOKUP(B33,대학별점수!$B$3:$M$74,7,0) -> 48 | M33: =VLOOKUP(B33,대학별점수!$B$3:$M$74,8,0) -> 45 | N33: =VLOOKUP(B33,대학별점수!$B$3:$M$74,9,0) -> 58 | O33: =VLOOKUP(B33,대학별점수!$B$3:$T$73,19,0) -> 157 | P33: =VLOOKUP(B33,대학별점수!$B$3:$V$74,18,0) -> 176 | Q33: =VLOOKUP(B33,대학별점수!$B$3:$V$74,17,0) -> _ | R33: =VLOOKUP(B33,대학별점수!$B$3:$V$74,16,0) -> 48 | S33: =VLOOKUP(B33,대학별점수!$B$3:$V$74,20,0) -> 6.44 | T33: =VLOOKUP(B33,대학별점수!$B$3:$V$74,21,0) -> 6.69 | U33: 실기기본점수 160점/변별력 상승
A34: 충남 | B34: =대학별점수!B34 -> 서원대 헬스케어운동 | C34: ='내신(남)'!B33 -> 200 | D34: =VLOOKUP(B34,대학별점수!$B$3:$C$74,2,FALSE) -> 193 | E34: =VLOOKUP(B34,대학별점수!$B$3:$D$74,3,FALSE) -> 175 | F34: =C34-D34 -> 7 | G34: ='실기환산(남)'!AF2 -> 800 | H34: =C34+G34 -> 1000 | I34: =VLOOKUP(B34,대학별점수!$B$3:$M$74,4,0) -> 986.6 | J34: =VLOOKUP(B34,대학별점수!$B$3:$M$74,5,0) -> 971.4 | K34: =VLOOKUP(B34,대학별점수!$B$3:$T$73,6,0) -> 25 | L34: =VLOOKUP(B34,대학별점수!$B$3:$M$74,7,0) -> 25 | M34: =VLOOKUP(B34,대학별점수!$B$3:$M$74,8,0) -> 25 | N34: =VLOOKUP(B34,대학별점수!$B$3:$M$74,9,0) -> 30 | O34: =VLOOKUP(B34,대학별점수!$B$3:$T$73,19,0) -> 46 | P34: =VLOOKUP(B34,대학별점수!$B$3:$V$74,18,0) -> 60 | Q34: =VLOOKUP(B34,대학별점수!$B$3:$V$74,17,0) -> _ | R34: =VLOOKUP(B34,대학별점수!$B$3:$V$74,16,0) -> 23신설 | S34: =VLOOKUP(B34,대학별점수!$B$3:$V$74,20,0) -> 8.24 | T34: =VLOOKUP(B34,대학별점수!$B$3:$V$74,21,0) -> 7.24 | U34: 실기기본점수 160점/변별력 상승
A35: 충남 | B35: =대학별점수!B35 -> 선문대 스포츠과학 | C35: ='내신(남)'!B34 -> 200 | D35: =VLOOKUP(B35,대학별점수!$B$3:$C$74,2,FALSE) -> 120 | E35: =VLOOKUP(B35,대학별점수!$B$3:$D$74,3,FALSE) -> 40 | F35: =C35-D35 -> 80 | G35: ='실기환산(남)'!AG2 -> 800 | H35: =C35+G35 -> 1000 | I35: =VLOOKUP(B35,대학별점수!$B$3:$M$74,4,0) -> 830 | J35: =VLOOKUP(B35,대학별점수!$B$3:$M$74,5,0) -> 795 | K35: =VLOOKUP(B35,대학별점수!$B$3:$T$73,6,0) -> 27 | L35: =VLOOKUP(B35,대학별점수!$B$3:$M$74,7,0) -> 26 | M35: =VLOOKUP(B35,대학별점수!$B$3:$M$74,8,0) -> 24 | N35: =VLOOKUP(B35,대학별점수!$B$3:$M$74,9,0) -> 25 | O35: =VLOOKUP(B35,대학별점수!$B$3:$T$73,19,0) -> 16 | P35: =VLOOKUP(B35,대학별점수!$B$3:$V$74,18,0) -> 33 | Q35: =VLOOKUP(B35,대학별점수!$B$3:$V$74,17,0) -> 18 | R35: =VLOOKUP(B35,대학별점수!$B$3:$V$74,16,0) -> 63 | S35: =VLOOKUP(B35,대학별점수!$B$3:$V$74,20,0) -> 5.35 | T35: =VLOOKUP(B35,대학별점수!$B$3:$V$74,21,0) -> 5.22 | U35: .
